Workbook

Sheet Chi phí
B2: Tổng chi phí | D2: Đã Thu | E2: Tiền lời
B3: =SUM(C6:C721) + 7291000 -> 1.0489072e+09 | D3: ='Xuất kho'!O2 +'Doanh thu'!I2 + 'Doanh thu 2025'!I2 + 'Doanh số'!I1 -> 1223080853 | E3: =D3-B3 -> 1.7417363e+08
A5: Tháng | B5: Nội dung khoản chi/thu | C5: Chi phí | D5: Doanh thu | E5: Note
A6: 45261 | B6: đăng kí kinh doanh | C6: 2000000
B7: 3 app | C7: 800000
B8: Phiếu giao + tem quay video | C8: 46000
B9: Thankyou card | C9: 120000
B10: Tem | C10: 170000
B11: Tăng follow facebook | C11: 30000
B12: Phí rút tiền shopee | C12: 11000
B13: Shopee Ads | C13: 330000
B14: Ship MCN | C14: =133840+271600+252280 -> 657720
B15: Viettel post | C15: =57000*2+33000 -> 147000
B16: Nạp tệ | C16: =4000000+700000+772000+2983500-2145000 -> 6310500
B17: Hộp đựng | C17: =87089+99000-30429 -> 155660
B18: Lixi 6868 shopee + túi ni lông | C18: =368400+733200+303000+425000+360000+19500 -> 2209100
B19: Phí đơn ảo | C19: =356000-338740+310550-298128+99600-95786+285599-270675+321200-303352+218800-192548 -> 92520
A20: 45292 | B20: Nạp tệ | C20: =1053000+57*3510-101*3510+4212000-1404000+1755000 -> 5461560
B21: Ship MCN | C21: =548800-28000*1.1-91560 -> 426440
B22: Viettel post | C22: =32000+32000+32000+32000+47000+32000-(32000/3.35*1.1+15000) -> 181492.54
B23: Shopee Ads | C23: =55000+220000+200000 -> 475000
B24: Hộp đựng + băng keo + decal | C24: =98580+128107+71000+91800 -> 389487
B25: Thuế | C25: 600000
B26: Acc tiktok | C26: 500000
A27: 45323 | B27: Nạp tệ | C27: =2800000+3510000+3520000+1760000 -> 11590000
B28: Shopee Ads | C28: 200000
B29: Ship MCN | C29: =241920+265160 -> 507080
B30: Ship Viettel | C30: =52002+57002 -> 109004
B31: Thuế | C31: 600000
B32: Hộp đựng | C32: 189910
A33: 45352 | B33: Nạp tệ | C33: =6001000+1775000*2+4260000+2485000-1200000+2142000+2856000+5712000+1071000+1428000 -> 28305000
B34: Ship MCN | C34: =349160+108640+495600+116200+309120+94080 -> 1472800
B35: Ship Viettel | C35: =72002+32002+97006+67000 -> 268010
B36: Hộp đựng | C36: =71000+147000 -> 218000
B37: Túi bóng | C37: 51500
B38: Gói hút ẩm + túi gói hàng | C38: 91500
B39: Kệ | C39: 302500
B40: Thuế | C40: 600000
B41: Phí rút tiền shopee | C41: =55000+11000 -> 66000
B42: Tiền ship viettel post 19/03 | C42: 32000
...

Sheet Net Income
B3: Doanh Thu | C3: Chi Phí | D3: Lãi Ròng
A4: 45261 | C4: =SUM('Chi phí'!C6:C19) -> 13079500 | D4: =B4-C4 -> -13079500
A5: 45292 | C5: =SUM('Chi phí'!C20:C26) -> 8033979.5 | D5: =B5-C5 -> -8033979.5
A6: 45323 | C6: =SUM('Chi phí'!C27:C32) -> 13195994 | D6: =B6-C6 -> -13195994
A7: 45352 | C7: =SUM('Chi phí'!C34:C45) -> 3485810 | D7: =B7-C7 -> -3485810
A8: 45383 | C8: =SUM('Chi phí'!C46:C53) -> 15971140 | D8: =B8-C8 -> -15971140
A9: 45413 | C9: =SUM('Chi phí'!C54:C68) -> 23124420 | D9: =B9-C9 -> -23124420
A10: 45444 | C10: =SUM('Chi phí'!C69:C83) -> 34601880 | D10: =B10-C10 -> -34601880
A11: 45474 | C11: =SUM('Chi phí'!C84:C102) -> 27773880 | D11: =B11-C11 -> -27773880
A12: 45505 | C12: =SUM('Chi phí'!C103:C115) -> 30550900 | D12: =B12-C12 -> -30550900
A13: 45536 | C13: =SUM('Chi phí'!C116:C123) -> 38220000 | D13: =B13-C13 -> -38220000
A14: 45566 | C14: =SUM('Chi phí'!C124:C130) -> 20323200 | D14: =B14-C14 -> -20323200
A15: 45597 | C15: =SUM('Chi phí'!C131:C138) -> 27708400 | D15: =B15-C15 -> -27708400
A16: 45627 | C16: =SUM('Chi phí'!C139:C145) -> 78888000 | D16: =B16-C16 -> -78888000
A17: 45658 | B17: =SUM('Doanh thu 2025'!H3:H476) -> 23677332 | C17: =SUM('Chi phí'!C146:C148) -> 2008000 | D17: =B17-C17 -> 21669332
A18: 45689 | B18: =SUM('Doanh thu 2025'!H477:H987) -> 34180085 | C18: =SUM('Chi phí'!C149:C174) -> 31033000 | D18: =B18-C18 -> 3147085
A19: 45717 | B19: =SUM('Doanh thu 2025'!H988:H2134) -> 72400566 | C19: =SUM('Chi phí'!C175:C192) -> 38768000 | D19: =B19-C19 -> 33632566
A20: 45748 | B20: =SUM('Doanh thu 2025'!H2135:H2748) -> 35953072 | C20: =SUM('Chi phí'!C193:C199) -> 34814000 | D20: =B20-C20 -> 1139072
A21: 45778 | B21: =SUM('Doanh thu 2025'!H2749:H3681) -> 97348999 | C21: =SUM('Chi phí'!C200:C225) -> 46238000 | D21: =B21-C21 -> 51110999
A22: 45809 | B22: =SUM('Doanh thu 2025'!H3608:H3681) -> 51417797 | C22: =SUM('Chi phí'!C226:C251) -> 34939000 | D22: =B22-C22 -> 16478797
A23: 45839 | B23: =SUM('Doanh thu 2025'!H3682:H3725)+SUM('Doanh số'!G3:G389) -> 81605923 | C23: =SUM('Chi phí'!C252:C277) -> 70985000 | D23: =B23-C23 -> 10620923
A24: 45870 | B24: =SUM('Doanh số'!G390:G613) -> 63989768 | C24: =SUM('Chi phí'!C278:C303) -> 39284000 | D24: =B24-C24 -> 24705768
A25: 45901 | B25: =SUM('Doanh số'!G614:G652)+SUM('Doanh số'!H652) -> 75077277 | C25: =SUM('Chi phí'!C304:C329) -> 69331000 | D25: =B25-C25 -> 5746277
A26: 45931 | B26: =SUM('Doanh số'!G653:G951) +54165+98025+57946+83187+50353+58661+102450+128968+83187+30615+107325+99022+54981+57931+92729+98712 -> 75134577 | C26: =SUM('Chi phí'!C330:C355) -> 74381000 | D26: =B26-C26 -> 753577
A27: 45962 | B27: =SUM('Doanh số'!G952:G1156) -> 65795997 | C27: =SUM('Chi phí'!C356:C381) -> 32438200 | D27: =B27-C27 -> 33357797 | E27: 2851434
A28: 45992 | B28: =SUM('Doanh số'!G1157:G1220) -> 52698220 | C28: =SUM('Chi phí'!C382:C385) -> 52978000 | D28: =B28-C28 -> -279780
A29: 46023 | B29: =SUM('Doanh số'!G1221:G1251) -> 48899363 | C29: =SUM('Chi phí'!C386:C389) -> 12964000 | D29: =B29-C29 -> 35935363
A30: 46054 | B30: =SUM('Doanh số'!G1252:G1265) -> 24066901 | C30: =SUM('Chi phí'!C390:C394) -> 53201920 | D30: =B30-C30 -> -29135019
A31: 46082 | B31: =SUM('Doanh số'!G1266:G1307) -> 64711889 | C31: =SUM('Chi phí'!C395:C399) -> 36054000 | D31: =B31-C31 -> 28657889
A32: 46113 | B32: =SUM('Doanh số'!G1308:G1338) -> 46537462 | C32: =SUM('Chi phí'!C400:C404) -> 30463000 | D32: =B32-C32 -> 16074462
A33: 46144 | B33: =SUM('Doanh số'!G1339:G1368) -> 48027140 | C33: =SUM('Chi phí'!C405:C407) -> 18474000 | D33: =B33-C33 -> 29553140
A34: 46176 | B34: =SUM('Doanh số'!G1369:G1380) -> 5945840 | C34: =SUM('Chi phí'!C408:C420) -> 0 | D34: =B34-C34 -> 5945840
D35: =B35-C35 -> 0

Sheet Doanh số
A1: Doanh Số | I1: =SUM(G3:G3000) -> 589877399
A2: Ngày | B2: Mã sản phẩm | C2: Loại | D2: Tên sản phẩm | E2: Số lượng | F2: Giá sàn | G2: Doanh thu | H2: Ghi chú
A3: 22/7/2025 | B3: ccpmdt06 | C3: móc khóa | D3: =IFERROR(VLOOKUP(B3,'Thống kê'!$C$3:$D$970,2, FALSE),VLOOKUP(B3,'Thống kê v2 CC'!$A$3:$D$1005,3, FALSE)) -> 0 | E3: 1 | F3: 69000 | G3: 100058
B4: ccpmdt76 | C4: móc khóa | D4: =IFERROR(VLOOKUP(B4,'Thống kê'!$C$3:$D$970,2, FALSE),VLOOKUP(B4,'Thống kê v2 CC'!$A$3:$D$1005,3, FALSE)) -> Móc khóa mô hình Twinkle Mini | E4: 1 | F4: 68500
B5: ccpmdt34 | C5: móc khoá | D5: =IFERROR(VLOOKUP(B5,'Thống kê'!$C$3:$D$970,2, FALSE),VLOOKUP(B5,'Thống kê v2 CC'!$A$3:$D$1005,3, FALSE)) -> 0 | E5: 1 | F5: 68500 | G5: 47940
B6: ccpmdt63 | C6: móc khoá | D6: =IFERROR(VLOOKUP(B6,'Thống kê'!$C$3:$D$970,2, FALSE),VLOOKUP(B6,'Thống kê v2 CC'!$A$3:$D$1005,3, FALSE)) -> 0 | E6: 1 | F6: 68500 | G6: 99653
B7: ccpmdt76 | C7: móc khoá | D7: =IFERROR(VLOOKUP(B7,'Thống kê'!$C$3:$D$970,2, FALSE),VLOOKUP(B7,'Thống kê v2 CC'!$A$3:$D$1005,3, FALSE)) -> Móc khóa mô hình Twinkle Mini | E7: 1 | F7: 68500
B8: ccpmdt47 | C8: móc khoá | D8: =IFERROR(VLOOKUP(B8,'Thống kê'!$C$3:$D$970,2, FALSE),VLOOKUP(B8,'Thống kê v2 CC'!$A$3:$D$1005,3, FALSE)) -> 0 | E8: 1 | F8: 69000 | G8: 48311
B9: ccpmdt19 | C9: móc khoá | D9: =IFERROR(VLOOKUP(B9,'Thống kê'!$C$3:$D$970,2, FALSE),VLOOKUP(B9,'Thống kê v2 CC'!$A$3:$D$1005,3, FALSE)) -> 0 | E9: 1 | F9: 68500 | G9: 99653
B10: ccpmdt75 | C10: móc khoá | D10: =IFERROR(VLOOKUP(B10,'Thống kê'!$C$3:$D$970,2, FALSE),VLOOKUP(B10,'Thống kê v2 CC'!$A$3:$D$1005,3, FALSE)) -> 0 | E10: 1 | F10: 68500
B11: ccpmdt74 | C11: móc khoá | D11: =IFERROR(VLOOKUP(B11,'Thống kê'!$C$3:$D$970,2, FALSE),VLOOKUP(B11,'Thống kê v2 CC'!$A$3:$D$1005,3, FALSE)) -> 0 | E11: 1 | F11: 68500 | G11: 47940
B12: ccpmdt58 - ct06 | C12: dây đeo điện thoại | D12: =IFERROR(VLOOKUP(B12,'Thống kê'!$C$3:$D$970,2, FALSE),VLOOKUP(B12,'Thống kê v2 CC'!$A$3:$D$1005,3, FALSE)) -> #N/A | E12: 1 | F12: 131000 | G12: 190889
B13: ccpmdt76 - ct06 | C13: dây đeo điện thoại | D13: =IFERROR(VLOOKUP(B13,'Thống kê'!$C$3:$D$970,2, FALSE),VLOOKUP(B13,'Thống kê v2 CC'!$A$3:$D$1005,3, FALSE)) -> #N/A | E13: 1 | F13: 131000
B14: ccpmdt75 | C14: móc khoá | D14: =IFERROR(VLOOKUP(B14,'Thống kê'!$C$3:$D$970,2, FALSE),VLOOKUP(B14,'Thống kê v2 CC'!$A$3:$D$1005,3, FALSE)) -> 0 | E14: 1 | F14: 68500 | G14: 99653
B15: ccpmdt74 | C15: móc khoá | D15: =IFERROR(VLOOKUP(B15,'Thống kê'!$C$3:$D$970,2, FALSE),VLOOKUP(B15,'Thống kê v2 CC'!$A$3:$D$1005,3, FALSE)) -> 0 | E15: 1 | F15: 68500
B16: ccpmdt63 | C16: móc khoá | D16: =IFERROR(VLOOKUP(B16,'Thống kê'!$C$3:$D$970,2, FALSE),VLOOKUP(B16,'Thống kê v2 CC'!$A$3:$D$1005,3, FALSE)) -> 0 | E16: 1 | F16: 68500 | G16: 99024
B17: ccpmdt82 | C17: móc khoá | D17: =IFERROR(VLOOKUP(B17,'Thống kê'!$C$3:$D$970,2, FALSE),VLOOKUP(B17,'Thống kê v2 CC'!$A$3:$D$1005,3, FALSE)) -> #N/A | E17: 1 | F17: 68500
B18: ccpmdt52 | C18: móc khoá | D18: =IFERROR(VLOOKUP(B18,'Thống kê'!$C$3:$D$970,2, FALSE),VLOOKUP(B18,'Thống kê v2 CC'!$A$3:$D$1005,3, FALSE)) -> 0 | E18: 1 | F18: 69000 | G18: 47682
B19: mkb04 | C19: móc khoá | D19: =IFERROR(VLOOKUP(B19,'Thống kê'!$C$3:$D$970,2, FALSE),VLOOKUP(B19,'Thống kê v2 CC'!$A$3:$D$1005,3, FALSE)) -> thỏ | E19: 1 | F19: 32200 | G19: 22880
B20: ccpmdt60 | C20: móc khoá | D20: =IFERROR(VLOOKUP(B20,'Thống kê'!$C$3:$D$970,2, FALSE),VLOOKUP(B20,'Thống kê v2 CC'!$A$3:$D$1005,3, FALSE)) -> 0 | E20: 1 | F20: 68500 | G20: 47940
B21: ccpmdt16 | C21: móc khoá | D21: =IFERROR(VLOOKUP(B21,'Thống kê'!$C$3:$D$970,2, FALSE),VLOOKUP(B21,'Thống kê v2 CC'!$A$3:$D$1005,3, FALSE)) -> 0 | E21: 1 | F21: 68500 | G21: 47316
B22: ccpmdt82 | C22: móc khoá | D22: =IFERROR(VLOOKUP(B22,'Thống kê'!$C$3:$D$970,2, FALSE),VLOOKUP(B22,'Thống kê v2 CC'!$A$3:$D$1005,3, FALSE)) -> #N/A | E22: 1 | F22: 68500 | G22: 146494
B23: ccpmdt76 | C23: móc khoá | D23: =IFERROR(VLOOKUP(B23,'Thống kê'!$C$3:$D$970,2, FALSE),VLOOKUP(B23,'Thống kê v2 CC'!$A$3:$D$1005,3, FALSE)) -> Móc khóa mô hình Twinkle Mini | E23: 1 | F23: 68500
B24: ccpmdt72 | C24: móc khoá | D24: =IFERROR(VLOOKUP(B24,'Thống kê'!$C$3:$D$970,2, FALSE),VLOOKUP(B24,'Thống kê v2 CC'!$A$3:$D$1005,3, FALSE)) -> 0 | E24: 1 | F24: 68500
B25: ccpmdt78 | C25: móc khoá | D25: =IFERROR(VLOOKUP(B25,'Thống kê'!$C$3:$D$970,2, FALSE),VLOOKUP(B25,'Thống kê v2 CC'!$A$3:$D$1005,3, FALSE)) -> 0 | E25: 1 | F25: 68500 | G25: 99653
B26: ccpmdt72 | C26: móc khoá | D26: =IFERROR(VLOOKUP(B26,'Thống kê'!$C$3:$D$970,2, FALSE),VLOOKUP(B26,'Thống kê v2 CC'!$A$3:$D$1005,3, FALSE)) -> 0 | E26: 1 | F26: 68500
B27: ccpmdt06 | C27: móc khoá | D27: =IFERROR(VLOOKUP(B27,'Thống kê'!$C$3:$D$970,2, FALSE),VLOOKUP(B27,'Thống kê v2 CC'!$A$3:$D$1005,3, FALSE)) -> 0 | E27: 1 | F27: 69000 | G27: 100058
B28: ccpmdt76 | C28: móc khoá | D28: =IFERROR(VLOOKUP(B28,'Thống kê'!$C$3:$D$970,2, FALSE),VLOOKUP(B28,'Thống kê v2 CC'!$A$3:$D$1005,3, FALSE)) -> Móc khóa mô hình Twinkle Mini | E28: 1 | F28: 68500
A29: 45861 | B29: ccpmdt83 | C29: móc khoá | D29: =IFERROR(VLOOKUP(B29,'Thống kê'!$C$3:$D$970,2, FALSE),VLOOKUP(B29,'Thống kê v2 CC'!$A$3:$D$1005,3, FALSE)) -> #N/A | E29: 1 | F29: 68500 | G29: 47316
B30: ccpmdt81 | C30: móc khoá | D30: =IFERROR(VLOOKUP(B30,'Thống kê'!$C$3:$D$970,2, FALSE),VLOOKUP(B30,'Thống kê v2 CC'!$A$3:$D$1005,3, FALSE)) -> #N/A | E30: 1 | F30: 68500 | G30: 99653
B31: ccpmdt82 | C31: móc khoá | D31: =IFERROR(VLOOKUP(B31,'Thống kê'!$C$3:$D$970,2, FALSE),VLOOKUP(B31,'Thống kê v2 CC'!$A$3:$D$1005,3, FALSE)) -> #N/A | E31: 1 | F31: 68500
B32: ccpmdt65 | C32: móc khoá | D32: =IFERROR(VLOOKUP(B32,'Thống kê'!$C$3:$D$970,2, FALSE),VLOOKUP(B32,'Thống kê v2 CC'!$A$3:$D$1005,3, FALSE)) -> 0 | E32: 1 | F32: 68500 | G32: 47316
B33: ccpmdt79 | C33: móc khoá | D33: =IFERROR(VLOOKUP(B33,'Thống kê'!$C$3:$D$970,2, FALSE),VLOOKUP(B33,'Thống kê v2 CC'!$A$3:$D$1005,3, FALSE)) -> #N/A | E33: 1 | F33: 68500 | G33: 47940
B34: ccpmdt65 | C34: móc khoá | D34: =IFERROR(VLOOKUP(B34,'Thống kê'!$C$3:$D$970,2, FALSE),VLOOKUP(B34,'Thống kê v2 CC'!$A$3:$D$1005,3, FALSE)) -> 0 | E34: 1 | F34: 68500 | G34: 139584
B35: ccpmdt50 | C35: móc khoá | D35: =IFERROR(VLOOKUP(B35,'Thống kê'!$C$3:$D$970,2, FALSE),VLOOKUP(B35,'Thống kê v2 CC'!$A$3:$D$1005,3, FALSE)) -> 0 | E35: 1 | F35: 59000
B36: ccpmdt76 | C36: móc khoá | D36: =IFERROR(VLOOKUP(B36,'Thống kê'!$C$3:$D$970,2, FALSE),VLOOKUP(B36,'Thống kê v2 CC'!$A$3:$D$1005,3, FALSE)) -> Móc khóa mô hình Twinkle Mini | E36: 1 | F36: 68500
B37: ccpmdt34 | C37: móc khoá | D37: =IFERROR(VLOOKUP(B37,'Thống kê'!$C$3:$D$970,2, FALSE),VLOOKUP(B37,'Thống kê v2 CC'!$A$3:$D$1005,3, FALSE)) -> 0 | E37: 1 | F37: 68500 | G37: 47940
B38: ccpmdt74 | C38: móc khoá | D38: =IFERROR(VLOOKUP(B38,'Thống kê'!$C$3:$D$970,2, FALSE),VLOOKUP(B38,'Thống kê v2 CC'!$A$3:$D$1005,3, FALSE)) -> 0 | E38: 1 | F38: 68500 | G38: 47316
B39: ccpmdt61 | C39: móc khoá | D39: =IFERROR(VLOOKUP(B39,'Thống kê'!$C$3:$D$970,2, FALSE),VLOOKUP(B39,'Thống kê v2 CC'!$A$3:$D$1005,3, FALSE)) -> 0 | E39: 1 | F39: 68500 | G39: 47316
B40: ggvmn03 | C40: ví mini | D40: =IFERROR(VLOOKUP(B40,'Thống kê'!$C$3:$D$970,2, FALSE),VLOOKUP(B40,'Thống kê v2 CC'!$A$3:$D$1005,3, FALSE)) -> Túi đựng đồ trang điểm nhỏ | E40: 1 | F40: 39200 | G40: 28301
...

Sheet Thống kê v2 CC
A1: Cửa hàng Chút Chíu
A3: Mã | B3: Kiểu dáng | C3: Tên sản phẩm | D3: Hình ảnh | E3: Nhập | F3: Xuất | G3: Tồn
A4: Crybaby01 | B4: Mô hình | C4: POP BEAN Pajama Party | E4: =+ SUMIF('Nhập kho T42024'!B:B, A4,'Nhập kho T42024'!F:F) -> 67 | F4: =+ SUMIF('Doanh thu 2025'!B:B, A4,'Doanh thu 2025'!E:E) -> 1 | G4: =E4-F4 -> 66
A5: Crybaby01-ct00 | B5: Móc khóa | C5: POP BEAN Pajama Party | E5: =+ SUMIF('Nhập kho T42024'!B:B, A5,'Nhập kho T42024'!F:F) -> 0 | F5: =+ SUMIF('Doanh thu 2025'!B:B, A5,'Doanh thu 2025'!E:E) -> 7 | G5: =E5-F5 -> -7
A6: Crybaby01-ct03 | B6: Móc khóa | C6: POP BEAN Pajama Party | E6: =+ SUMIF('Nhập kho T42024'!B:B, A6,'Nhập kho T42024'!F:F) -> 0 | F6: =+ SUMIF('Doanh thu 2025'!B:B, A6,'Doanh thu 2025'!E:E) -> 5 | G6: =E6-F6+4 -> -1
A7: crybaby01-ct06 | B7: Móc khóa | C7: POP BEAN Pajama Party | E7: =+ SUMIF('Nhập kho T42024'!B:B, A7,'Nhập kho T42024'!F:F) -> 10 | F7: =+ SUMIF('Doanh thu 2025'!B:B, A7,'Doanh thu 2025'!E:E) -> 2 | G7: =E7-F7+4 -> 12
A8: crybaby02-ct05 | B8: Móc khóa | C8: Pop Bean Popmart | E8: =+ SUMIF('Nhập kho T42024'!B:B, A8,'Nhập kho T42024'!F:F) -> 10 | F8: =+ SUMIF('Doanh thu 2025'!B:B, A8,'Doanh thu 2025'!E:E) -> 0 | G8: =E8-F8+4 -> 14
A9: Dimoo01 | B9: Mô hình | C9: POP BEAN Pajama Party | E9: =+ SUMIF('Nhập kho T42024'!B:B, A9,'Nhập kho T42024'!F:F) -> 20 | F9: =+ SUMIF('Doanh thu 2025'!B:B, A9,'Doanh thu 2025'!E:E) -> 0 | G9: =E9-F9 -> 20
A10: Dimoo01-ct00 | B10: Móc khóa | C10: POP BEAN Pajama Party | E10: =+ SUMIF('Nhập kho T42024'!B:B, A10,'Nhập kho T42024'!F:F) -> 0 | F10: =+ SUMIF('Doanh thu 2025'!B:B, A10,'Doanh thu 2025'!E:E) -> 2 | G10: =E10-F10 -> -2
A11: Dimoo02 | B11: Mô hình | C11: POP BEAN Pajama Party | E11: =+ SUMIF('Nhập kho T42024'!B:B, A11,'Nhập kho T42024'!F:F) -> 5 | F11: =+ SUMIF('Doanh thu 2025'!B:B, A11,'Doanh thu 2025'!E:E) -> 0 | G11: =E11-F11 -> 5
A12: Dimoo02-ct00 | B12: Móc khóa | C12: POP BEAN Pajama Party | E12: =+ SUMIF('Nhập kho T42024'!B:B, A12,'Nhập kho T42024'!F:F) -> 0 | F12: =+ SUMIF('Doanh thu 2025'!B:B, A12,'Doanh thu 2025'!E:E) -> 3 | G12: =E12-F12 -> -3
A13: Hacipupu01 | B13: Mô hình | C13: POP BEAN Pajama Party | E13: =+ SUMIF('Nhập kho T42024'!B:B, A13,'Nhập kho T42024'!F:F) -> 3 | F13: =+ SUMIF('Doanh thu 2025'!B:B, A13,'Doanh thu 2025'!E:E) -> 0 | G13: =E13-F13 -> 3
A14: Hacipupu01-ct00 | B14: Móc khóa | C14: POP BEAN Pajama Party | E14: =+ SUMIF('Nhập kho T42024'!B:B, A14,'Nhập kho T42024'!F:F) -> 0 | F14: =+ SUMIF('Doanh thu 2025'!B:B, A14,'Doanh thu 2025'!E:E) -> 0 | G14: =E14-F14 -> 0
A15: Kubo01 | B15: Mô hình | C15: POP BEAN Pajama Party | E15: =+ SUMIF('Nhập kho T42024'!B:B, A15,'Nhập kho T42024'!F:F) -> 30 | F15: =+ SUMIF('Doanh thu 2025'!B:B, A15,'Doanh thu 2025'!E:E) -> 1 | G15: =E15-F15 -> 29
A16: Kubo01-ct00 | B16: Móc khóa | C16: POP BEAN Pajama Party | E16: =+ SUMIF('Nhập kho T42024'!B:B, A16,'Nhập kho T42024'!F:F) -> 0 | F16: =+ SUMIF('Doanh thu 2025'!B:B, A16,'Doanh thu 2025'!E:E) -> 4 | G16: =E16-F16 -> -4
A17: Kubo01-ct03 | B17: Móc khóa | C17: POP BEAN Pajama Party | E17: =+ SUMIF('Nhập kho T42024'!B:B, A17,'Nhập kho T42024'!F:F) -> 0 | F17: =+ SUMIF('Doanh thu 2025'!B:B, A17,'Doanh thu 2025'!E:E) -> 1 | G17: =E17-F17+2 -> 1
A18: Labubu01 | B18: Mô hình | C18: POP BEAN Pajama Party | E18: =+ SUMIF('Nhập kho T42024'!B:B, A18,'Nhập kho T42024'!F:F) -> 2 | F18: =+ SUMIF('Doanh thu 2025'!B:B, A18,'Doanh thu 2025'!E:E) -> 0 | G18: =E18-F18 -> 2
A19: Labubu01-ct00 | B19: Móc khóa | C19: POP BEAN Pajama Party | E19: =+ SUMIF('Nhập kho T42024'!B:B, A19,'Nhập kho T42024'!F:F) -> 0 | F19: =+ SUMIF('Doanh thu 2025'!B:B, A19,'Doanh thu 2025'!E:E) -> 0 | G19: =E19-F19 -> 0
A20: Molly01 | B20: Mô hình | C20: POP BEAN Pajama Party | E20: =+ SUMIF('Nhập kho T42024'!B:B, A20,'Nhập kho T42024'!F:F) -> 6 | F20: =+ SUMIF('Doanh thu 2025'!B:B, A20,'Doanh thu 2025'!E:E) -> 0 | G20: =E20-F20 -> 6
A21: Molly01-ct00 | B21: Móc khóa | C21: POP BEAN Pajama Party | E21: =+ SUMIF('Nhập kho T42024'!B:B, A21,'Nhập kho T42024'!F:F) -> 0 | F21: =+ SUMIF('Doanh thu 2025'!B:B, A21,'Doanh thu 2025'!E:E) -> 1 | G21: =E21-F21 -> -1
A22: Nyota01 | B22: Mô hình | C22: POP BEAN Pajama Party | E22: =+ SUMIF('Nhập kho T42024'!B:B, A22,'Nhập kho T42024'!F:F) -> 2 | F22: =+ SUMIF('Doanh thu 2025'!B:B, A22,'Doanh thu 2025'!E:E) -> 0 | G22: =E22-F22 -> 2
A23: Nyota01-ct00 | B23: Móc khóa | C23: POP BEAN Pajama Party | E23: =+ SUMIF('Nhập kho T42024'!B:B, A23,'Nhập kho T42024'!F:F) -> 0 | F23: =+ SUMIF('Doanh thu 2025'!B:B, A23,'Doanh thu 2025'!E:E) -> 2 | G23: =E23-F23 -> -2
A24: Pino01 | B24: Mô hình | C24: POP BEAN Pajama Party | E24: =+ SUMIF('Nhập kho T42024'!B:B, A24,'Nhập kho T42024'!F:F) -> 7 | F24: =+ SUMIF('Doanh thu 2025'!B:B, A24,'Doanh thu 2025'!E:E) -> 0 | G24: =E24-F24 -> 7
A25: Pino01-ct00 | B25: Móc khóa | C25: POP BEAN Pajama Party | E25: =+ SUMIF('Nhập kho T42024'!B:B, A25,'Nhập kho T42024'!F:F) -> 0 | F25: =+ SUMIF('Doanh thu 2025'!B:B, A25,'Doanh thu 2025'!E:E) -> 1 | G25: =E25-F25 -> -1
A26: Pucky01 | B26: Mô hình | C26: POP BEAN Pajama Party | E26: =+ SUMIF('Nhập kho T42024'!B:B, A26,'Nhập kho T42024'!F:F) -> 2 | F26: =+ SUMIF('Doanh thu 2025'!B:B, A26,'Doanh thu 2025'!E:E) -> 0 | G26: =E26-F26 -> 2
A27: Pucky01-ct00 | B27: Móc khóa | C27: POP BEAN Pajama Party | E27: =+ SUMIF('Nhập kho T42024'!B:B, A27,'Nhập kho T42024'!F:F) -> 0 | F27: =+ SUMIF('Doanh thu 2025'!B:B, A27,'Doanh thu 2025'!E:E) -> 1 | G27: =E27-F27 -> -1
A28: Skullpanda01 | B28: Mô hình | C28: POP BEAN Pajama Party | E28: =+ SUMIF('Nhập kho T42024'!B:B, A28,'Nhập kho T42024'!F:F) -> 40 | F28: =+ SUMIF('Doanh thu 2025'!B:B, A28,'Doanh thu 2025'!E:E) -> 0 | G28: =E28-F28 -> 40
A29: Skullpanda01-ct00 | B29: Móc khóa | C29: POP BEAN Pajama Party | E29: =+ SUMIF('Nhập kho T42024'!B:B, A29,'Nhập kho T42024'!F:F) -> 0 | F29: =+ SUMIF('Doanh thu 2025'!B:B, A29,'Doanh thu 2025'!E:E) -> 2 | G29: =E29-F29 -> -2
A30: Skullpanda01-ct03 | E30: =+ SUMIF('Nhập kho T42024'!B:B, A30,'Nhập kho T42024'!F:F) -> 0 | F30: =+ SUMIF('Doanh thu 2025'!B:B, A30,'Doanh thu 2025'!E:E) -> 1 | G30: =E30-F30+1 -> 0
A31: skullpanda02-ct05 | B31: Móc khóa | C31: Pop Bean Popmart | E31: =+ SUMIF('Nhập kho T42024'!B:B, A31,'Nhập kho T42024'!F:F) -> 10 | F31: =+ SUMIF('Doanh thu 2025'!B:B, A31,'Doanh thu 2025'!E:E) -> 1 | G31: =E31-F31+1 -> 10
A32: skullpanda03-ct06 | B32: Móc khóa | C32: Pop Bean Popmart | E32: =+ SUMIF('Nhập kho T42024'!B:B, A32,'Nhập kho T42024'!F:F) -> 10 | F32: =+ SUMIF('Doanh thu 2025'!B:B, A32,'Doanh thu 2025'!E:E) -> 1 | G32: =E32-F32+1 -> 10
A33: Sweetbean01 | B33: Mô hình | C33: POP BEAN Pajama Party | E33: =+ SUMIF('Nhập kho T42024'!B:B, A33,'Nhập kho T42024'!F:F) -> 5 | F33: =+ SUMIF('Doanh thu 2025'!B:B, A33,'Doanh thu 2025'!E:E) -> 0 | G33: =E33-F33 -> 5
A34: Sweetbean01-ct00 | B34: Móc khóa | C34: POP BEAN Pajama Party | E34: =+ SUMIF('Nhập kho T42024'!B:B, A34,'Nhập kho T42024'!F:F) -> 0 | F34: =+ SUMIF('Doanh thu 2025'!B:B, A34,'Doanh thu 2025'!E:E) -> 0 | G34: =E34-F34 -> 0
A35: Twinkle01 | B35: Mô hình | C35: POP BEAN Pajama Party | E35: =+ SUMIF('Nhập kho T42024'!B:B, A35,'Nhập kho T42024'!F:F) -> 4 | F35: =+ SUMIF('Doanh thu 2025'!B:B, A35,'Doanh thu 2025'!E:E) -> 0 | G35: =E35-F35 -> 4
A36: Twinkle01-ct00 | B36: Móc khóa | C36: POP BEAN Pajama Party | E36: =+ SUMIF('Nhập kho T42024'!B:B, A36,'Nhập kho T42024'!F:F) -> 0 | F36: =+ SUMIF('Doanh thu 2025'!B:B, A36,'Doanh thu 2025'!E:E) -> 1 | G36: =E36-F36 -> -1
A37: Zsiga01 | B37: Mô hình | C37: POP BEAN Pajama Party | E37: =+ SUMIF('Nhập kho T42024'!B:B, A37,'Nhập kho T42024'!F:F) -> 4 | F37: =+ SUMIF('Doanh thu 2025'!B:B, A37,'Doanh thu 2025'!E:E) -> 0 | G37: =E37-F37 -> 4
A38: Zsiga01-ct00 | B38: Móc khóa | C38: POP BEAN Pajama Party | E38: =+ SUMIF('Nhập kho T42024'!B:B, A38,'Nhập kho T42024'!F:F) -> 0 | F38: =+ SUMIF('Doanh thu 2025'!B:B, A38,'Doanh thu 2025'!E:E) -> 0 | G38: =E38-F38 -> 0
A39: Zsiga02 | B39: Mô hình | C39: POP BEAN Pajama Party | E39: =+ SUMIF('Nhập kho T42024'!B:B, A39,'Nhập kho T42024'!F:F) -> 7 | F39: =+ SUMIF('Doanh thu 2025'!B:B, A39,'Doanh thu 2025'!E:E) -> 0 | G39: =E39-F39 -> 7
A40: Zsiga02-ct00 | B40: Móc khóa | C40: POP BEAN Pajama Party | E40: =+ SUMIF('Nhập kho T42024'!B:B, A40,'Nhập kho T42024'!F:F) -> 0 | F40: =+ SUMIF('Doanh thu 2025'!B:B, A40,'Doanh thu 2025'!E:E) -> 0 | G40: =E40-F40 -> 0
A41: Zsiga03-ct06 | B41: Móc khóa | C41: Pop Bean Popmart | E41: =+ SUMIF('Nhập kho T42024'!B:B, A41,'Nhập kho T42024'!F:F) -> 5 | F41: =+ SUMIF('Doanh thu 2025'!B:B, A41,'Doanh thu 2025'!E:E) -> 2 | G41: =E41-F41 -> 3
...

Sheet Thống kê
B1: DANH MỤC HÀNG HÓA
B2: STT | C2: Mã hàng | D2: Tên quy cách | E2: ĐVT | F2: Giá bán | G2: Nhập | H2: Xuất | I2: Tồn | J2: Tổng doanh thu | K2: Doanh thu T4 | L2: Tổng nhập | M2: Tổng số bán | N2: Lợi nhuận
A3: TÚI CHƯỜM BỤNG | B3: 1 | C3: TCB01 | D3: Túi chườm bụng trái bơ 1000ml | E3: túi | F3: 101150 | G3: =+ SUMIF('Nhập kho T42024'!B:B, C3,'Nhập kho T42024'!F:F) -> 4 | H3: =+ SUMIF('Doanh thu'!A:A, C3,'Doanh thu'!E:E) + SUMIF('Doanh thu 2025'!B:B, C3,'Doanh thu 2025'!E:E) -> 5 | I3: =G3-H3 -> -1 | J3: =SUM(K3) -> 404600 | K3: =+ SUMIF('Doanh thu'!A:A, C3,'Doanh thu'!F:F) -> 404600
B4: 1 | C4: TCB01-500 | D4: Túi chườm bụng trái bơ 500ml | E4: túi | F4: 78200 | G4: =+ SUMIF('Nhập kho T42024'!B:B, C4,'Nhập kho T42024'!F:F) -> 6 | H4: =+ SUMIF('Doanh thu'!A:A, C4,'Doanh thu'!E:E) + SUMIF('Doanh thu 2025'!B:B, C4,'Doanh thu 2025'!E:E) -> 6 | I4: =G4-H4+1 -> 1 | J4: =SUM(K4) -> 469200 | K4: =+ SUMIF('Doanh thu'!A:A, C4,'Doanh thu'!F:F) -> 469200
B5: 1 | C5: TCB02 | D5: Túi chườm bụng dâu (xanh) 1000ml | E5: túi | F5: 101150 | G5: =+ SUMIF('Nhập kho T42024'!B:B, C5,'Nhập kho T42024'!F:F) -> 4 | H5: =+ SUMIF('Doanh thu'!A:A, C5,'Doanh thu'!E:E) + SUMIF('Doanh thu 2025'!B:B, C5,'Doanh thu 2025'!E:E) -> 7 | I5: =G5-H5+3 -> 0 | J5: =SUM(K5) -> 708050 | K5: =+ SUMIF('Doanh thu'!A:A, C5,'Doanh thu'!F:F) -> 708050
B6: 1 | C6: TCB02-500 | D6: Túi chườm bụng dâu (xanh) 500ml | E6: túi | F6: 78200 | G6: =+ SUMIF('Nhập kho T42024'!B:B, C6,'Nhập kho T42024'!F:F) -> 6 | H6: =+ SUMIF('Doanh thu'!A:A, C6,'Doanh thu'!E:E) + SUMIF('Doanh thu 2025'!B:B, C6,'Doanh thu 2025'!E:E) -> 4 | I6: =G6-H6 -> 2 | J6: =SUM(K6) -> 234600 | K6: =+ SUMIF('Doanh thu'!A:A, C6,'Doanh thu'!F:F) -> 234600
B7: 1 | C7: TCB03 | D7: Túi chườm bụng dâu (hồng đất) 1000ml | E7: túi | F7: 101150 | G7: =+ SUMIF('Nhập kho T42024'!B:B, C7,'Nhập kho T42024'!F:F) -> 3 | H7: =+ SUMIF('Doanh thu'!A:A, C7,'Doanh thu'!E:E) + SUMIF('Doanh thu 2025'!B:B, C7,'Doanh thu 2025'!E:E) -> 8 | I7: =G7-H7+3 -> -2 | J7: =SUM(K7) -> 708050 | K7: =+ SUMIF('Doanh thu'!A:A, C7,'Doanh thu'!F:F) -> 708050
B8: 1 | C8: TCB03-500 | D8: Túi chườm bụng dâu (hồng đất) 500ml | E8: túi | F8: 78200 | G8: =+ SUMIF('Nhập kho T42024'!B:B, C8,'Nhập kho T42024'!F:F) -> 6 | H8: =+ SUMIF('Doanh thu'!A:A, C8,'Doanh thu'!E:E) + SUMIF('Doanh thu 2025'!B:B, C8,'Doanh thu 2025'!E:E) -> 0 | I8: =G8-H8 -> 6 | J8: =SUM(K8) -> 0 | K8: =+ SUMIF('Doanh thu'!A:A, C8,'Doanh thu'!F:F) -> 0
B9: 1 | C9: TCB04 | D9: Túi chườm bụng dứa (xanh đậm) 1000ml | E9: túi | F9: 101150 | G9: =+ SUMIF('Nhập kho T42024'!B:B, C9,'Nhập kho T42024'!F:F) -> 5 | H9: =+ SUMIF('Doanh thu'!A:A, C9,'Doanh thu'!E:E) + SUMIF('Doanh thu 2025'!B:B, C9,'Doanh thu 2025'!E:E) -> 10 | I9: =G9-H9+1 -> -4 | J9: =SUM(K9) -> 910350 | K9: =+ SUMIF('Doanh thu'!A:A, C9,'Doanh thu'!F:F) -> 910350
B10: 1 | C10: TCB04-500 | D10: Túi chườm bụng dứa (xanh đậm) 500ml | E10: túi | F10: 78200 | G10: =+ SUMIF('Nhập kho T42024'!B:B, C10,'Nhập kho T42024'!F:F) -> 3 | H10: =+ SUMIF('Doanh thu'!A:A, C10,'Doanh thu'!E:E) + SUMIF('Doanh thu 2025'!B:B, C10,'Doanh thu 2025'!E:E) -> 4 | I10: =G10-H10+3 -> 2 | J10: =SUM(K10) -> 312800 | K10: =+ SUMIF('Doanh thu'!A:A, C10,'Doanh thu'!F:F) -> 312800
B11: 1 | C11: TCB05 | D11: Túi chườm bụng thỏ và dứa 1000ml | E11: túi | F11: 101500 | G11: =+ SUMIF('Nhập kho T42024'!B:B, C11,'Nhập kho T42024'!F:F) -> 5 | H11: =+ SUMIF('Doanh thu'!A:A, C11,'Doanh thu'!E:E) + SUMIF('Doanh thu 2025'!B:B, C11,'Doanh thu 2025'!E:E) -> 4 | I11: =G11-H11-1 -> 0 | J11: =SUM(K11) -> 406000 | K11: =+ SUMIF('Doanh thu'!A:A, C11,'Doanh thu'!F:F) -> 406000
B12: 1 | C12: TCB05-500 | D12: Túi chườm bụng thỏ và dứa 500ml | E12: túi | F12: 78200 | G12: =+ SUMIF('Nhập kho T42024'!B:B, C12,'Nhập kho T42024'!F:F) -> 5 | H12: =+ SUMIF('Doanh thu'!A:A, C12,'Doanh thu'!E:E) + SUMIF('Doanh thu 2025'!B:B, C12,'Doanh thu 2025'!E:E) -> 3 | I12: =G12-H12+1 -> 3 | J12: =SUM(K12) -> 156400 | K12: =+ SUMIF('Doanh thu'!A:A, C12,'Doanh thu'!F:F) -> 156400
B13: 1 | C13: TCB11 | D13: Túi chườm bụng trái bơ 500ml | E13: túi | F13: 72250 | G13: =+ SUMIF('Nhập kho T42024'!B:B, C13,'Nhập kho T42024'!F:F) -> 0 | H13: =+ SUMIF('Doanh thu'!A:A, C13,'Doanh thu'!E:E) + SUMIF('Doanh thu 2025'!B:B, C13,'Doanh thu 2025'!E:E) -> 0 | I13: =G13-H13 -> 0 | J13: =SUM(K13) -> 0 | K13: =+ SUMIF('Doanh thu'!A:A, C13,'Doanh thu'!F:F) -> 0
B14: 1 | C14: TCB12 | D14: Túi chườm bụng dâu tây 500ml | E14: túi | F14: 72250 | G14: =+ SUMIF('Nhập kho T42024'!B:B, C14,'Nhập kho T42024'!F:F) -> 0 | H14: =+ SUMIF('Doanh thu'!A:A, C14,'Doanh thu'!E:E) + SUMIF('Doanh thu 2025'!B:B, C14,'Doanh thu 2025'!E:E) -> 0 | I14: =G14-H14 -> 0 | J14: =SUM(K14) -> 0 | K14: =+ SUMIF('Doanh thu'!A:A, C14,'Doanh thu'!F:F) -> 0
B15: 1 | C15: TCB13 | D15: Túi chườm bụng dứa xanh đậm 500ml | E15: túi | F15: 72250 | G15: =+ SUMIF('Nhập kho T42024'!B:B, C15,'Nhập kho T42024'!F:F) -> 0 | H15: =+ SUMIF('Doanh thu'!A:A, C15,'Doanh thu'!E:E) + SUMIF('Doanh thu 2025'!B:B, C15,'Doanh thu 2025'!E:E) -> 0 | I15: =G15-H15 -> 0 | J15: =SUM(K15) -> 0 | K15: =+ SUMIF('Doanh thu'!A:A, C15,'Doanh thu'!F:F) -> 0
B16: 1 | C16: TCB14 | D16: Túi chườm bụng dâu xanh nhạt 500ml | E16: túi | F16: 72250 | G16: =+ SUMIF('Nhập kho T42024'!B:B, C16,'Nhập kho T42024'!F:F) -> 0 | H16: =+ SUMIF('Doanh thu'!A:A, C16,'Doanh thu'!E:E) + SUMIF('Doanh thu 2025'!B:B, C16,'Doanh thu 2025'!E:E) -> 0 | I16: =G16-H16 -> 0 | J16: =SUM(K16) -> 0 | K16: =+ SUMIF('Doanh thu'!A:A, C16,'Doanh thu'!F:F) -> 0
B17: 1 | C17: TCB15 | D17: Túi chườm bụng thỏ dứa 500ml | E17: túi | F17: 72250 | G17: =+ SUMIF('Nhập kho T42024'!B:B, C17,'Nhập kho T42024'!F:F) -> 0 | H17: =+ SUMIF('Doanh thu'!A:A, C17,'Doanh thu'!E:E) + SUMIF('Doanh thu 2025'!B:B, C17,'Doanh thu 2025'!E:E) -> 0 | I17: =G17-H17 -> 0 | J17: =SUM(K17) -> 0 | K17: =+ SUMIF('Doanh thu'!A:A, C17,'Doanh thu'!F:F) -> 0
B18: 1 | C18: TCB16 | D18: Túi chườm bụng gấu nâu 500ml | E18: túi | F18: 72250 | G18: =+ SUMIF('Nhập kho T42024'!B:B, C18,'Nhập kho T42024'!F:F) -> 0 | H18: =+ SUMIF('Doanh thu'!A:A, C18,'Doanh thu'!E:E) + SUMIF('Doanh thu 2025'!B:B, C18,'Doanh thu 2025'!E:E) -> 8 | I18: =G18-H18+8 -> 0 | J18: =SUM(K18) -> 578000 | K18: =+ SUMIF('Doanh thu'!A:A, C18,'Doanh thu'!F:F) -> 578000
B19: 1 | C19: TCB17 | D19: Túi chườm bụng vịt vàng 500ml | E19: túi | F19: 72250 | G19: =+ SUMIF('Nhập kho T42024'!B:B, C19,'Nhập kho T42024'!F:F) -> 0 | H19: =+ SUMIF('Doanh thu'!A:A, C19,'Doanh thu'!E:E) + SUMIF('Doanh thu 2025'!B:B, C19,'Doanh thu 2025'!E:E) -> 5 | I19: =G19-H19+6 -> 1 | J19: =SUM(K19) -> 361250 | K19: =+ SUMIF('Doanh thu'!A:A, C19,'Doanh thu'!F:F) -> 361250
B20: 1 | C20: TCB18 | D20: Túi chườm bụng thỏ hồng 500ml | E20: túi | F20: 72250 | G20: =+ SUMIF('Nhập kho T42024'!B:B, C20,'Nhập kho T42024'!F:F) -> 0 | H20: =+ SUMIF('Doanh thu'!A:A, C20,'Doanh thu'!E:E) + SUMIF('Doanh thu 2025'!B:B, C20,'Doanh thu 2025'!E:E) -> 9 | I20: =G20-H20+9 -> 0 | J20: =SUM(K20) -> 650250 | K20: =+ SUMIF('Doanh thu'!A:A, C20,'Doanh thu'!F:F) -> 650250
B21: 1 | C21: TCB19 | D21: Túi chườm bụng mèo be 500ml | E21: túi | F21: 72250 | G21: =+ SUMIF('Nhập kho T42024'!B:B, C21,'Nhập kho T42024'!F:F) -> 0 | H21: =+ SUMIF('Doanh thu'!A:A, C21,'Doanh thu'!E:E) + SUMIF('Doanh thu 2025'!B:B, C21,'Doanh thu 2025'!E:E) -> 0 | I21: =G21-H21 -> 0 | J21: =SUM(K21) -> 0 | K21: =+ SUMIF('Doanh thu'!A:A, C21,'Doanh thu'!F:F) -> 0
A22: BAO LÌ XÌ | B22: 1 | C22: LX01 | D22: Bao lì xì | E22: túi 4 cái | F22: 14500 | G22: =+ SUMIF('Nhập kho T42024'!B:B, C22,'Nhập kho T42024'!F:F) -> 70 | H22: =+ SUMIF('Doanh thu'!A:A, C22,'Doanh thu'!E:E) + SUMIF('Doanh thu 2025'!B:B, C22,'Doanh thu 2025'!E:E) -> 70 | I22: =G22-H22 -> 0 | J22: =SUM(K22) -> 14500 | K22: =+ SUMIF('Doanh thu'!A:A, C22,'Doanh thu'!F:F) -> 14500
B23: 1 | C23: LX02 | D23: Bao lì xì | E23: túi 4 cái | F23: 14500 | G23: =+ SUMIF('Nhập kho T42024'!B:B, C23,'Nhập kho T42024'!F:F) -> 70 | H23: =+ SUMIF('Doanh thu'!A:A, C23,'Doanh thu'!E:E) + SUMIF('Doanh thu 2025'!B:B, C23,'Doanh thu 2025'!E:E) -> 71 | I23: =G23-H23 -> -1 | J23: =SUM(K23) -> 87000 | K23: =+ SUMIF('Doanh thu'!A:A, C23,'Doanh thu'!F:F) -> 87000
B24: 1 | C24: LX03 | D24: Bao lì xì | E24: set 6 cái | F24: 14500 | G24: =+ SUMIF('Nhập kho T42024'!B:B, C24,'Nhập kho T42024'!F:F) -> 150 | H24: =+ SUMIF('Doanh thu'!A:A, C24,'Doanh thu'!E:E) + SUMIF('Doanh thu 2025'!B:B, C24,'Doanh thu 2025'!E:E) -> 69 | I24: =G24-H24 -> 81 | J24: =SUM(K24) -> 203000 | K24: =+ SUMIF('Doanh thu'!A:A, C24,'Doanh thu'!F:F) -> 203000
B25: 1 | C25: LX04 | D25: Bao lì xì | E25: set 6 cái | F25: 14500 | G25: =+ SUMIF('Nhập kho T42024'!B:B, C25,'Nhập kho T42024'!F:F) -> 130 | H25: =+ SUMIF('Doanh thu'!A:A, C25,'Doanh thu'!E:E) + SUMIF('Doanh thu 2025'!B:B, C25,'Doanh thu 2025'!E:E) -> 33 | I25: =G25-H25 -> 97 | J25: =SUM(K25) -> 29000 | K25: =+ SUMIF('Doanh thu'!A:A, C25,'Doanh thu'!F:F) -> 29000
B26: 1 | C26: LX05 | D26: Bao lì xì | E26: set 6 cái | F26: 14500 | G26: =+ SUMIF('Nhập kho T42024'!B:B, C26,'Nhập kho T42024'!F:F) -> 110 | H26: =+ SUMIF('Doanh thu'!A:A, C26,'Doanh thu'!E:E) + SUMIF('Doanh thu 2025'!B:B, C26,'Doanh thu 2025'!E:E) -> 49 | I26: =G26-H26 -> 61 | J26: =SUM(K26) -> 58000 | K26: =+ SUMIF('Doanh thu'!A:A, C26,'Doanh thu'!F:F) -> 58000
B27: 1 | C27: LX06 | D27: Bao lì xì | E27: set 6 cái | F27: 14500 | G27: =+ SUMIF('Nhập kho T42024'!B:B, C27,'Nhập kho T42024'!F:F) -> 70 | H27: =+ SUMIF('Doanh thu'!A:A, C27,'Doanh thu'!E:E) + SUMIF('Doanh thu 2025'!B:B, C27,'Doanh thu 2025'!E:E) -> 35 | I27: =G27-H27 -> 35 | J27: =SUM(K27) -> 116000 | K27: =+ SUMIF('Doanh thu'!A:A, C27,'Doanh thu'!F:F) -> 116000
B28: 1 | C28: LX07 | D28: Bao lì xì | E28: set 6 cái | F28: 14500 | G28: =+ SUMIF('Nhập kho T42024'!B:B, C28,'Nhập kho T42024'!F:F) -> 92 | H28: =+ SUMIF('Doanh thu'!A:A, C28,'Doanh thu'!E:E) + SUMIF('Doanh thu 2025'!B:B, C28,'Doanh thu 2025'!E:E) -> 4 | I28: =G28-H28 -> 88 | J28: =SUM(K28) -> 0 | K28: =+ SUMIF('Doanh thu'!A:A, C28,'Doanh thu'!F:F) -> 0
A29: PHỤ KIỆN THỜI TRANG | B29: 1 | C29: CA01 | D29: Cài áo hoa hồng đen | E29: cái | F29: 39500 | G29: =+ SUMIF('Nhập kho T42024'!B:B, C29,'Nhập kho T42024'!F:F) -> 0 | H29: =+ SUMIF('Doanh thu'!A:A, C29,'Doanh thu'!E:E) + SUMIF('Doanh thu 2025'!B:B, C29,'Doanh thu 2025'!E:E) -> 1 | I29: =G29-H29+3 -> 2 | J29: =SUM(K29) -> 0 | K29: =+ SUMIF('Doanh thu'!A:A, C29,'Doanh thu'!F:F) -> 0
B30: 1 | C30: CA02 | D30: Cài áo hoa hồng đỏ | E30: cái | F30: 39500 | G30: =+ SUMIF('Nhập kho T42024'!B:B, C30,'Nhập kho T42024'!F:F) -> 0 | H30: =+ SUMIF('Doanh thu'!A:A, C30,'Doanh thu'!E:E) + SUMIF('Doanh thu 2025'!B:B, C30,'Doanh thu 2025'!E:E) -> 0 | I30: =G30-H30+3 -> 3 | J30: =SUM(K30) -> 0 | K30: =+ SUMIF('Doanh thu'!A:A, C30,'Doanh thu'!F:F) -> 0
B31: 1 | C31: CA03 | D31: Cài áo hoa hồng xanh có ngọc trai | E31: cái | F31: 24900 | G31: =+ SUMIF('Nhập kho T42024'!B:B, C31,'Nhập kho T42024'!F:F) -> 0 | H31: =+ SUMIF('Doanh thu'!A:A, C31,'Doanh thu'!E:E) + SUMIF('Doanh thu 2025'!B:B, C31,'Doanh thu 2025'!E:E) -> 2 | I31: =G31-H31+2 -> 0 | J31: =SUM(K31) -> 49800 | K31: =+ SUMIF('Doanh thu'!A:A, C31,'Doanh thu'!F:F) -> 49800
B32: 1 | C32: CA04 | D32: Cài áo hoa hồng trắng có ngọc trai | E32: cái | F32: 24900 | G32: =+ SUMIF('Nhập kho T42024'!B:B, C32,'Nhập kho T42024'!F:F) -> 0 | H32: =+ SUMIF('Doanh thu'!A:A, C32,'Doanh thu'!E:E) + SUMIF('Doanh thu 2025'!B:B, C32,'Doanh thu 2025'!E:E) -> 1 | I32: =G32-H32+3 -> 2 | J32: =SUM(K32) -> 24900 | K32: =+ SUMIF('Doanh thu'!A:A, C32,'Doanh thu'!F:F) -> 24900
B33: 1 | C33: CA05 | D33: Cài áo ngọc trai bướm vàng | E33: cái | F33: 23900 | G33: =+ SUMIF('Nhập kho T42024'!B:B, C33,'Nhập kho T42024'!F:F) -> 0 | H33: =+ SUMIF('Doanh thu'!A:A, C33,'Doanh thu'!E:E) + SUMIF('Doanh thu 2025'!B:B, C33,'Doanh thu 2025'!E:E) -> 1 | I33: =G33-H33+3 -> 2 | J33: =SUM(K33) -> 23900 | K33: =+ SUMIF('Doanh thu'!A:A, C33,'Doanh thu'!F:F) -> 23900
B34: 1 | C34: CA06 | D34: Cài áo ngọc trai bướm bạc | E34: cái | F34: 23900 | G34: =+ SUMIF('Nhập kho T42024'!B:B, C34,'Nhập kho T42024'!F:F) -> 0 | H34: =+ SUMIF('Doanh thu'!A:A, C34,'Doanh thu'!E:E) + SUMIF('Doanh thu 2025'!B:B, C34,'Doanh thu 2025'!E:E) -> 0 | I34: =G34-H34+3 -> 3 | J34: =SUM(K34) -> 0 | K34: =+ SUMIF('Doanh thu'!A:A, C34,'Doanh thu'!F:F) -> 0
B35: 1 | C35: CA07 | D35: Cài áo tulip | E35: cái | F35: 23900 | G35: =+ SUMIF('Nhập kho T42024'!B:B, C35,'Nhập kho T42024'!F:F) -> 0 | H35: =+ SUMIF('Doanh thu'!A:A, C35,'Doanh thu'!E:E) + SUMIF('Doanh thu 2025'!B:B, C35,'Doanh thu 2025'!E:E) -> 0 | I35: =G35-H35 -> 0 | J35: =SUM(K35) -> 0 | K35: =+ SUMIF('Doanh thu'!A:A, C35,'Doanh thu'!F:F) -> 0
B36: 1 | C36: CA08 | D36: Cài áo lúa | E36: cái | F36: 23900 | G36: =+ SUMIF('Nhập kho T42024'!B:B, C36,'Nhập kho T42024'!F:F) -> 0 | H36: =+ SUMIF('Doanh thu'!A:A, C36,'Doanh thu'!E:E) + SUMIF('Doanh thu 2025'!B:B, C36,'Doanh thu 2025'!E:E) -> 0 | I36: =G36-H36 -> 0 | J36: =SUM(K36) -> 0 | K36: =+ SUMIF('Doanh thu'!A:A, C36,'Doanh thu'!F:F) -> 0
B37: 1 | C37: CA09 | D37: Cài áo xương rồng | E37: cái | F37: 37500 | G37: =+ SUMIF('Nhập kho T42024'!B:B, C37,'Nhập kho T42024'!F:F) -> 0 | H37: =+ SUMIF('Doanh thu'!A:A, C37,'Doanh thu'!E:E) + SUMIF('Doanh thu 2025'!B:B, C37,'Doanh thu 2025'!E:E) -> 0 | I37: =G37-H37+2 -> 2 | J37: =SUM(K37) -> 0 | K37: =+ SUMIF('Doanh thu'!A:A, C37,'Doanh thu'!F:F) -> 0
B38: 1 | C38: CA10 | D38: Cài áo trái tim vàng | E38: cái | F38: 22900 | G38: =+ SUMIF('Nhập kho T42024'!B:B, C38,'Nhập kho T42024'!F:F) -> 0 | H38: =+ SUMIF('Doanh thu'!A:A, C38,'Doanh thu'!E:E) + SUMIF('Doanh thu 2025'!B:B, C38,'Doanh thu 2025'!E:E) -> 1 | I38: =G38-H38+3 -> 2 | J38: =SUM(K38) -> 0 | K38: =+ SUMIF('Doanh thu'!A:A, C38,'Doanh thu'!F:F) -> 0
B39: 1 | C39: CA11 | D39: Cài áo trái tim bạc | E39: cái | F39: 22900 | G39: =+ SUMIF('Nhập kho T42024'!B:B, C39,'Nhập kho T42024'!F:F) -> 0 | H39: =+ SUMIF('Doanh thu'!A:A, C39,'Doanh thu'!E:E) + SUMIF('Doanh thu 2025'!B:B, C39,'Doanh thu 2025'!E:E) -> 2 | I39: =G39-H39+2 -> 0 | J39: =SUM(K39) -> 22900 | K39: =+ SUMIF('Doanh thu'!A:A, C39,'Doanh thu'!F:F) -> 22900
B40: 1 | C40: CA12 | D40: Cài áo kính vàng | E40: cái | F40: 12500 | G40: =+ SUMIF('Nhập kho T42024'!B:B, C40,'Nhập kho T42024'!F:F) -> 0 | H40: =+ SUMIF('Doanh thu'!A:A, C40,'Doanh thu'!E:E) + SUMIF('Doanh thu 2025'!B:B, C40,'Doanh thu 2025'!E:E) -> 2 | I40: =G40-H40+2 -> 0 | J40: =SUM(K40) -> 26500 | K40: =+ SUMIF('Doanh thu'!A:A, C40,'Doanh thu'!F:F) -> 26500
...

Sheet Nhập kho T42024
A1: Nhập kho
A2: Ngày | B2: Mã hàng | C2: Tên quy cách | D2: ĐVT | E2: Đơn giá | F2: Số lượng nhập | G2: Tổng | H2: VNĐ
A3: 2 | B3: KTHS07 | C3: =VLOOKUP(B3,'Danh mục hàng hóa'!$C$3:$D$643,2,0) -> Kẹp tóc hoa sứ đỏ hồng đậm | D3: =VLOOKUP(B3,'Danh mục hàng hóa'!$C$3:$E$656,3,0) -> cái | E3: 1.71 | F3: 5 | G3: =E3*F3 -> 8.55
B4: KTHS01 | C4: =VLOOKUP(B4,'Danh mục hàng hóa'!$C$3:$D$643,2,0) -> Kẹp tóc hoa sứ tím | D4: =VLOOKUP(B4,'Danh mục hàng hóa'!$C$3:$E$656,3,0) -> cái | E4: 1.71 | F4: 20 | G4: =E4*F4 -> 34.2
B5: KTHS02 | C5: =VLOOKUP(B5,'Danh mục hàng hóa'!$C$3:$D$643,2,0) -> Kẹp tóc hoa sứ hồng | D5: =VLOOKUP(B5,'Danh mục hàng hóa'!$C$3:$E$656,3,0) -> cái | E5: 1.71 | F5: 20 | G5: =E5*F5 -> 34.2
B6: KTHS06 | C6: =VLOOKUP(B6,'Danh mục hàng hóa'!$C$3:$D$643,2,0) -> Kẹp tóc hoa sứ xanh | D6: =VLOOKUP(B6,'Danh mục hàng hóa'!$C$3:$E$656,3,0) -> cái | E6: 1.71 | F6: 20 | G6: =E6*F6 -> 34.2
B7: KTHS03 | C7: =VLOOKUP(B7,'Danh mục hàng hóa'!$C$3:$D$643,2,0) -> Kẹp tóc hoa sứ vàng | D7: =VLOOKUP(B7,'Danh mục hàng hóa'!$C$3:$E$656,3,0) -> cái | E7: 1.71 | F7: 20 | G7: =E7*F7 -> 34.2
B8: KTHS05 | C8: =VLOOKUP(B8,'Danh mục hàng hóa'!$C$3:$D$643,2,0) -> Kẹp tóc hoa sứ đỏ | D8: =VLOOKUP(B8,'Danh mục hàng hóa'!$C$3:$E$656,3,0) -> cái | E8: 1.71 | F8: 20 | G8: =E8*F8 -> 34.2
B9: KTHS04 | C9: =VLOOKUP(B9,'Danh mục hàng hóa'!$C$3:$D$643,2,0) -> Kẹp tóc hoa sứ cam | D9: =VLOOKUP(B9,'Danh mục hàng hóa'!$C$3:$E$656,3,0) -> cái | E9: 1.71 | F9: 20 | G9: =E9*F9 -> 34.2
A10: 5 | B10: KTB11 | C10: =VLOOKUP(B10,'Danh mục hàng hóa'!$C$3:$D$643,2,0) -> Kẹp tóc bướm trắng | D10: =VLOOKUP(B10,'Danh mục hàng hóa'!$C$3:$E$656,3,0) -> cái | E10: 1.62 | F10: 9 | G10: =E10*F10 -> 14.58
B11: KTB08 | C11: =VLOOKUP(B11,'Danh mục hàng hóa'!$C$3:$D$643,2,0) -> Kẹp tóc bướm hồng đỏ | D11: =VLOOKUP(B11,'Danh mục hàng hóa'!$C$3:$E$656,3,0) -> cái | E11: 1.62 | F11: 9 | G11: =E11*F11 -> 14.58
B12: KTB09 | C12: =VLOOKUP(B12,'Danh mục hàng hóa'!$C$3:$D$643,2,0) -> Kẹp tóc bướm tím | D12: =VLOOKUP(B12,'Danh mục hàng hóa'!$C$3:$E$656,3,0) -> cái | E12: 1.62 | F12: 9 | G12: =E12*F12 -> 14.58
B13: KTB10 | C13: =VLOOKUP(B13,'Danh mục hàng hóa'!$C$3:$D$643,2,0) -> Kẹp tóc bướm cam | D13: =VLOOKUP(B13,'Danh mục hàng hóa'!$C$3:$E$656,3,0) -> cái | E13: 1.62 | F13: 9 | G13: =E13*F13 -> 14.58
B14: KTB13 | C14: =VLOOKUP(B14,'Danh mục hàng hóa'!$C$3:$D$643,2,0) -> Kẹp tóc bướm xanh da trời | D14: =VLOOKUP(B14,'Danh mục hàng hóa'!$C$3:$E$656,3,0) -> cái | E14: 1.55 | F14: 15 | G14: =E14*F14 -> 23.25
B15: KTB12 | C15: =VLOOKUP(B15,'Danh mục hàng hóa'!$C$3:$D$643,2,0) -> Kẹp tóc bướm xanh lá | D15: =VLOOKUP(B15,'Danh mục hàng hóa'!$C$3:$E$656,3,0) -> cái | E15: 1.55 | F15: 15 | G15: =E15*F15 -> 23.25
B16: KTB14 | C16: =VLOOKUP(B16,'Danh mục hàng hóa'!$C$3:$D$643,2,0) -> Kẹp tóc bướm tím | D16: =VLOOKUP(B16,'Danh mục hàng hóa'!$C$3:$E$656,3,0) -> cái | E16: 1.55 | F16: 15 | G16: =E16*F16 -> 23.25
B17: KTB15 | C17: =VLOOKUP(B17,'Danh mục hàng hóa'!$C$3:$D$643,2,0) -> Kẹp tóc bướm hồng nhạt | D17: =VLOOKUP(B17,'Danh mục hàng hóa'!$C$3:$E$656,3,0) -> cái | E17: 1.55 | F17: 15 | G17: =E17*F17 -> 23.25
B18: KTB16 | C18: =VLOOKUP(B18,'Danh mục hàng hóa'!$C$3:$D$643,2,0) -> Kẹp tóc bướm đen | D18: =VLOOKUP(B18,'Danh mục hàng hóa'!$C$3:$E$656,3,0) -> cái | E18: 1.55 | F18: 15 | G18: =E18*F18 -> 23.25
B19: TCB05-500 | C19: =VLOOKUP(B19,'Danh mục hàng hóa'!$C$3:$D$643,2,0) -> Túi chườm bụng thỏ dứa 500ml | D19: =VLOOKUP(B19,'Danh mục hàng hóa'!$C$3:$E$656,3,0) -> túi | E19: 9.76 | F19: 4 | G19: =E19*F19 -> 39.04
B20: TCB04 | C20: =VLOOKUP(B20,'Danh mục hàng hóa'!$C$3:$D$643,2,0) -> Túi chườm bụng dâu xanh nhạt 1000ml | D20: =VLOOKUP(B20,'Danh mục hàng hóa'!$C$3:$E$656,3,0) -> túi | E20: 11.57 | F20: 1 | G20: =E20*F20 -> 11.57
B21: TCB03 | C21: =VLOOKUP(B21,'Danh mục hàng hóa'!$C$3:$D$643,2,0) -> Túi chườm bụng dứa xanh đậm 1000ml | D21: =VLOOKUP(B21,'Danh mục hàng hóa'!$C$3:$E$656,3,0) -> túi | E21: 11.57 | F21: 1 | G21: =E21*F21 -> 11.57
B22: TCB02-500 | C22: =VLOOKUP(B22,'Danh mục hàng hóa'!$C$3:$D$643,2,0) -> Túi chườm bụng dâu (xanh) 500ml | D22: =VLOOKUP(B22,'Danh mục hàng hóa'!$C$3:$E$656,3,0) -> túi | E22: 9.76 | F22: 3 | G22: =E22*F22 -> 29.28
... B27: TCB02 | C27: =VLOOKUP(B27,'Danh mục hàng hóa'!$C$3:$D$643,2,0) -> Túi chườm bụng dâu (xanh) 1000ml | D27: =VLOOKUP(B27,'Danh mục hàng hóa'!$C$3:$E$656,3,0) -> túi | E27: 11.57 | F27: 1 | G27: =E27*F27 -> 11.57
A28: 10 | B28: MCC | C28: =VLOOKUP(B28,'Danh mục hàng hóa'!$C$3:$D$643,2,0) -> Mèo chong chóng | D28: =VLOOKUP(B28,'Danh mục hàng hóa'!$C$3:$E$656,3,0) -> cái | E28: 6.76 | F28: 3 | G28: =E28*F28 -> 20.28
B29: TCC02 | C29: =VLOOKUP(B29,'Danh mục hàng hóa'!$C$3:$D$643,2,0) -> Thỏ ú bay | D29: =VLOOKUP(B29,'Danh mục hàng hóa'!$C$3:$E$656,3,0) -> cái | E29: 7.62 | F29: 4 | G29: =E29*F29 -> 30.48
B30: VCC | C30: =VLOOKUP(B30,'Danh mục hàng hóa'!$C$3:$D$643,2,0) -> Vịt ú bay | D30: =VLOOKUP(B30,'Danh mục hàng hóa'!$C$3:$E$656,3,0) -> cái | E30: 7.62 | F30: 12 | G30: =E30*F30 -> 91.44
B31: HCC02 | C31: =VLOOKUP(B31,'Danh mục hàng hóa'!$C$3:$D$643,2,0) -> Heo ú bay | D31: =VLOOKUP(B31,'Danh mục hàng hóa'!$C$3:$E$656,3,0) -> cái | E31: 7.62 | F31: 5 | G31: =E31*F31 -> 38.1
B32: TCC | C32: =VLOOKUP(B32,'Danh mục hàng hóa'!$C$3:$D$643,2,0) -> Thỏ chong chóng | D32: =VLOOKUP(B32,'Danh mục hàng hóa'!$C$3:$E$656,3,0) -> cái | E32: 6.76 | F32: 8 | G32: =E32*F32 -> 54.08
B33: GCC | C33: =VLOOKUP(B33,'Danh mục hàng hóa'!$C$3:$D$643,2,0) -> Gấu chong chóng | D33: =VLOOKUP(B33,'Danh mục hàng hóa'!$C$3:$E$656,3,0) -> cái | E33: 6.76 | F33: 3 | G33: =E33*F33 -> 20.28
B34: HCC | C34: =VLOOKUP(B34,'Danh mục hàng hóa'!$C$3:$D$643,2,0) -> Heo ú | D34: =VLOOKUP(B34,'Danh mục hàng hóa'!$C$3:$E$656,3,0) -> cái | E34: 6.76 | F34: 12 | G34: =E34*F34 -> 81.12
B35: MCC02 | C35: =VLOOKUP(B35,'Danh mục hàng hóa'!$C$3:$D$643,2,0) -> Mèo ú bay | D35: =VLOOKUP(B35,'Danh mục hàng hóa'!$C$3:$E$656,3,0) -> cái | E35: 7.62 | F35: 2 | G35: =E35*F35 -> 15.24
B36: KTB06 | C36: =VLOOKUP(B36,'Danh mục hàng hóa'!$C$3:$D$643,2,0) -> Kẹp tóc bướm trắng | D36: =VLOOKUP(B36,'Danh mục hàng hóa'!$C$3:$E$656,3,0) -> cái | E36: 4.75 | F36: 20 | G36: =E36*F36 -> 95
B37: KTB04 | C37: =VLOOKUP(B37,'Danh mục hàng hóa'!$C$3:$D$643,2,0) -> Kẹp tóc bướm xanh tím | D37: =VLOOKUP(B37,'Danh mục hàng hóa'!$C$3:$E$656,3,0) -> cái | E37: 4.75 | F37: 20 | G37: =E37*F37 -> 95
B38: KTB22 | C38: =VLOOKUP(B38,'Danh mục hàng hóa'!$C$3:$D$643,2,0) -> Kẹp tóc bướm hồng | D38: =VLOOKUP(B38,'Danh mục hàng hóa'!$C$3:$E$656,3,0) -> cái | E38: 4.75 | F38: 60 | G38: =E38*F38 -> 285
B39: KTB01 | C39: =VLOOKUP(B39,'Danh mục hàng hóa'!$C$3:$D$643,2,0) -> Kẹp tóc bướm hồng phấn | D39: =VLOOKUP(B39,'Danh mục hàng hóa'!$C$3:$E$656,3,0) -> cái | E39: 4.75 | F39: 60 | G39: =E39*F39 -> 285
B40: KTB06 | C40: =VLOOKUP(B40,'Danh mục hàng hóa'!$C$3:$D$643,2,0) -> Kẹp tóc bướm trắng | D40: =VLOOKUP(B40,'Danh mục hàng hóa'!$C$3:$E$656,3,0) -> cái | E40: 4.75 | F40: 10 | G40: =E40*F40 -> 47.5
... B68: KTB20 | C68: =VLOOKUP(B68,'Danh mục hàng hóa'!$C$3:$D$643,2,0) -> Kẹp tóc bướm xanh vàng | D68: =VLOOKUP(B68,'Danh mục hàng hóa'!$C$3:$E$656,3,0) -> cái | E68: 5.6 | F68: 15 | G68: =E68*F68 -> 84
A69: 14 | B69: KTB19 | C69: =VLOOKUP(B69,'Danh mục hàng hóa'!$C$3:$D$643,2,0) -> Kẹp tóc bướm hồng loang xanh | D69: =VLOOKUP(B69,'Danh mục hàng hóa'!$C$3:$E$656,3,0) -> cái | E69: 5.7 | F69: 10 | G69: =E69*F69 -> 57
B70: KTB18 | C70: =VLOOKUP(B70,'Danh mục hàng hóa'!$C$3:$D$643,2,0) -> Kẹp tóc bướm xanh trắng | D70: =VLOOKUP(B70,'Danh mục hàng hóa'!$C$3:$E$656,3,0) -> cái | E70: 5.7 | F70: 20 | G70: =E70*F70 -> 114
B71: KTB23 | C71: =VLOOKUP(B71,'Danh mục hàng hóa'!$C$3:$D$643,2,0) -> Kẹp tóc bướm trắng | D71: =VLOOKUP(B71,'Danh mục hàng hóa'!$C$3:$E$656,3,0) -> cái | E71: 5.7 | F71: 10 | G71: =E71*F71 -> 57
...

Sheet Doanh thu 2025
A1: 2025
A2: Ngày | B2: Mã hàng | C2: Tên quy cách | D2: Đơn giá bán | E2: Số lượng xuất | F2: Xuất | G2: Note | H2: Doanh thu | I2: =SUM(H3:H5494) -> 324180102
A3: 45658 | B3: bán kẹp | C3: =VLOOKUP(B3,'Thống kê'!$C$3:$D$669,2,0) -> #N/A | D3: =VLOOKUP(B3,'Danh mục hàng hóa'!$C$3:$M$656,6,0) -> #N/A | F3: =D3*E3 -> #N/A | H3: 800000
B4: mkcb01 | C4: =VLOOKUP(B4,'Thống kê'!$C$3:$D$669,2,0) -> Móc khoá Crybaby mini Popmart | D4: =VLOOKUP(B4,'Danh mục hàng hóa'!$C$3:$M$656,6,0) -> #N/A | E4: 1 | F4: =D4*E4 -> #N/A | H4: 93700
A5: 45659 | B5: vcc | C5: =VLOOKUP(B5,'Thống kê'!$C$3:$D$669,2,0) -> Vịt ú bay | D5: =VLOOKUP(B5,'Danh mục hàng hóa'!$C$3:$M$656,6,0) -> 64500 | E5: 1 | F5: =D5*E5 -> 64500 | H5: 56256
B6: mkcb01 | C6: =VLOOKUP(B6,'Thống kê'!$C$3:$D$669,2,0) -> Móc khoá Crybaby mini Popmart | D6: =VLOOKUP(B6,'Danh mục hàng hóa'!$C$3:$M$656,6,0) -> #N/A | E6: 1 | F6: =D6*E6 -> #N/A | H6: 91020
B7: hcc | C7: =VLOOKUP(B7,'Thống kê'!$C$3:$D$669,2,0) -> Heo ú | D7: =VLOOKUP(B7,'Danh mục hàng hóa'!$C$3:$M$656,6,0) -> 61275 | E7: 1 | F7: =D7*E7 -> 61275 | H7: 48195
B8: mcc | C8: =VLOOKUP(B8,'Thống kê'!$C$3:$D$669,2,0) -> Mèo ú | D8: =VLOOKUP(B8,'Danh mục hàng hóa'!$C$3:$M$656,6,0) -> 54740 | F8: =D8*E8 -> 0 | H8: 96760
B9: gcc | C9: =VLOOKUP(B9,'Thống kê'!$C$3:$D$669,2,0) -> Gấu ú | D9: =VLOOKUP(B9,'Danh mục hàng hóa'!$C$3:$M$656,6,0) -> 56525 | F9: =D9*E9 -> 0
B10: mkdm02 | C10: =VLOOKUP(B10,'Thống kê'!$C$3:$D$669,2,0) -> Móc khoá Dimoo size mini (hàng remake) | D10: =VLOOKUP(B10,'Danh mục hàng hóa'!$C$3:$M$656,6,0) -> #N/A | F10: =D10*E10 -> #N/A | H10: 190733
B11: mkpm53 | C11: =VLOOKUP(B11,'Thống kê'!$C$3:$D$669,2,0) -> 0 | D11: =VLOOKUP(B11,'Danh mục hàng hóa'!$C$3:$M$656,6,0) -> #N/A | F11: =D11*E11 -> #N/A
B12: lotdt | C12: =VLOOKUP(B12,'Thống kê'!$C$3:$D$669,2,0) -> miếng dán silicon điện thoại | D12: =VLOOKUP(B12,'Danh mục hàng hóa'!$C$3:$M$656,6,0) -> #N/A | F12: =D12*E12 -> #N/A
B13: hcc | C13: =VLOOKUP(B13,'Thống kê'!$C$3:$D$669,2,0) -> Heo ú | D13: =VLOOKUP(B13,'Danh mục hàng hóa'!$C$3:$M$656,6,0) -> 61275 | F13: =D13*E13 -> 0 | H13: 47895
B14: mkd11 | C14: =VLOOKUP(B14,'Thống kê'!$C$3:$D$669,2,0) -> Móc khóa có chuông | D14: =VLOOKUP(B14,'Danh mục hàng hóa'!$C$3:$M$656,6,0) -> #N/A | F14: =D14*E14 -> #N/A | H14: 45135
B15: tcc02 | C15: =VLOOKUP(B15,'Thống kê'!$C$3:$D$669,2,0) -> Thỏ ú bay | D15: =VLOOKUP(B15,'Danh mục hàng hóa'!$C$3:$M$656,6,0) -> 61275 | F15: =D15*E15 -> 0 | H15: 253101
B16: scc | C16: =VLOOKUP(B16,'Thống kê'!$C$3:$D$669,2,0) -> Shiba ú cầm hoa | D16: =VLOOKUP(B16,'Danh mục hàng hóa'!$C$3:$M$656,6,0) -> #N/A | F16: =D16*E16 -> #N/A
B17: tmbgx | C17: =VLOOKUP(B17,'Thống kê'!$C$3:$D$669,2,0) -> Thỏ máy bay gắn xe | D17: =VLOOKUP(B17,'Danh mục hàng hóa'!$C$3:$M$656,6,0) -> 59340 | F17: =D17*E17 -> 0
B18: tcxgx | C18: =VLOOKUP(B18,'Thống kê'!$C$3:$D$669,2,0) -> Thỏ chạy xe gắn xe | D18: =VLOOKUP(B18,'Danh mục hàng hóa'!$C$3:$M$656,6,0) -> 59340 | F18: =D18*E18 -> 0
B19: mkbn08 | C19: =VLOOKUP(B19,'Thống kê'!$C$3:$D$669,2,0) -> Móc khóa chuối | D19: =VLOOKUP(B19,'Danh mục hàng hóa'!$C$3:$M$656,6,0) -> #N/A | F19: =D19*E19 -> #N/A
B20: lotdt | C20: =VLOOKUP(B20,'Thống kê'!$C$3:$D$669,2,0) -> miếng dán silicon điện thoại | D20: =VLOOKUP(B20,'Danh mục hàng hóa'!$C$3:$M$656,6,0) -> #N/A | F20: =D20*E20 -> #N/A
B21: mkg05 | C21: =VLOOKUP(B21,'Thống kê'!$C$3:$D$669,2,0) -> 0 | D21: =VLOOKUP(B21,'Danh mục hàng hóa'!$C$3:$M$656,6,0) -> #N/A | E21: 2 | F21: =D21*E21 -> #N/A | H21: 620000
B22: mkg06 | C22: =VLOOKUP(B22,'Thống kê'!$C$3:$D$669,2,0) -> 0 | D22: =VLOOKUP(B22,'Danh mục hàng hóa'!$C$3:$M$656,6,0) -> #N/A | E22: 2 | F22: =D22*E22 -> #N/A
B23: mkg07 | C23: =VLOOKUP(B23,'Thống kê'!$C$3:$D$669,2,0) -> 0 | D23: =VLOOKUP(B23,'Danh mục hàng hóa'!$C$3:$M$656,6,0) -> #N/A | E23: 2 | F23: =D23*E23 -> #N/A
B24: mkg09 | C24: =VLOOKUP(B24,'Thống kê'!$C$3:$D$669,2,0) -> 0 | D24: =VLOOKUP(B24,'Danh mục hàng hóa'!$C$3:$M$656,6,0) -> #N/A | E24: 2 | F24: =D24*E24 -> #N/A
B25: mkg10 | C25: =VLOOKUP(B25,'Thống kê'!$C$3:$D$669,2,0) -> 0 | D25: =VLOOKUP(B25,'Danh mục hàng hóa'!$C$3:$M$656,6,0) -> #N/A | E25: 2 | F25: =D25*E25 -> #N/A
B26: mdm09 | C26: =VLOOKUP(B26,'Thống kê'!$C$3:$D$669,2,0) -> 0 | D26: =VLOOKUP(B26,'Danh mục hàng hóa'!$C$3:$M$656,6,0) -> #N/A | E26: 1 | F26: =D26*E26 -> #N/A | H26: 124640
B27: hcc04 | C27: =VLOOKUP(B27,'Thống kê'!$C$3:$D$669,2,0) -> heo ú cầm hoa | D27: =VLOOKUP(B27,'Danh mục hàng hóa'!$C$3:$M$656,6,0) -> #N/A | E27: 1 | F27: =D27*E27 -> #N/A | H27: 88560
B28: tcxgx | C28: =VLOOKUP(B28,'Thống kê'!$C$3:$D$669,2,0) -> Thỏ chạy xe gắn xe | D28: =VLOOKUP(B28,'Danh mục hàng hóa'!$C$3:$M$656,6,0) -> 59340 | E28: 1 | F28: =D28*E28 -> 59340
A29: 45660 | B29: mkpm26 | C29: =VLOOKUP(B29,'Thống kê'!$C$3:$D$669,2,0) -> Móc khóa Popbean Kubo | D29: =VLOOKUP(B29,'Danh mục hàng hóa'!$C$3:$M$656,6,0) -> #N/A | E29: 1 | F29: =D29*E29 -> #N/A | H29: 178038
B30: mkpm27 | C30: =VLOOKUP(B30,'Thống kê'!$C$3:$D$669,2,0) -> Móc khóa Popbean Cry Baby | D30: =VLOOKUP(B30,'Danh mục hàng hóa'!$C$3:$M$656,6,0) -> #N/A | E30: 1 | F30: =D30*E30 -> #N/A
B31: lotdt | C31: =VLOOKUP(B31,'Thống kê'!$C$3:$D$669,2,0) -> miếng dán silicon điện thoại | D31: =VLOOKUP(B31,'Danh mục hàng hóa'!$C$3:$M$656,6,0) -> #N/A | E31: 1 | F31: =D31*E31 -> #N/A
B32: mcc02 | C32: =VLOOKUP(B32,'Thống kê'!$C$3:$D$669,2,0) -> Mèo ú bay | D32: =VLOOKUP(B32,'Danh mục hàng hóa'!$C$3:$M$656,6,0) -> 61275 | E32: 1 | F32: =D32*E32 -> 61275 | H32: 56456
B33: lx01(6bao) | C33: =VLOOKUP(B33,'Thống kê'!$C$3:$D$669,2,0) -> bao lì xì Tết 2025 | D33: =VLOOKUP(B33,'Danh mục hàng hóa'!$C$3:$M$656,6,0) -> #N/A | E33: 2 | F33: =D33*E33 -> #N/A | H33: 33195
B34: lx03(6bao) | C34: =VLOOKUP(B34,'Thống kê'!$C$3:$D$669,2,0) -> bao lì xì Tết 2025 | D34: =VLOOKUP(B34,'Danh mục hàng hóa'!$C$3:$M$656,6,0) -> #N/A | E34: 1 | F34: =D34*E34 -> #N/A
B35: lx06(6bao) | C35: =VLOOKUP(B35,'Thống kê'!$C$3:$D$669,2,0) -> bao lì xì Tết 2025 | D35: =VLOOKUP(B35,'Danh mục hàng hóa'!$C$3:$M$656,6,0) -> #N/A | E35: 1 | F35: =D35*E35 -> #N/A
B36: lx04(6bao) | C36: =VLOOKUP(B36,'Thống kê'!$C$3:$D$669,2,0) -> bao lì xì Tết 2025 | D36: =VLOOKUP(B36,'Danh mục hàng hóa'!$C$3:$M$656,6,0) -> #N/A | E36: 1 | F36: =D36*E36 -> #N/A
B37: mkpm40 | C37: =VLOOKUP(B37,'Thống kê'!$C$3:$D$669,2,0) -> Móc khóa Popbean | D37: =VLOOKUP(B37,'Danh mục hàng hóa'!$C$3:$M$656,6,0) -> #N/A | E37: 1 | F37: =D37*E37 -> #N/A | H37: 128740
B38: lotdt | C38: =VLOOKUP(B38,'Thống kê'!$C$3:$D$669,2,0) -> miếng dán silicon điện thoại | D38: =VLOOKUP(B38,'Danh mục hàng hóa'!$C$3:$M$656,6,0) -> #N/A | E38: 1 | F38: =D38*E38 -> #N/A
B39: mkcb01 | C39: =VLOOKUP(B39,'Thống kê'!$C$3:$D$669,2,0) -> Móc khoá Crybaby mini Popmart | D39: =VLOOKUP(B39,'Danh mục hàng hóa'!$C$3:$M$656,6,0) -> #N/A | E39: 1 | F39: =D39*E39 -> #N/A | H39: 91020
B40: lotdt | C40: =VLOOKUP(B40,'Thống kê'!$C$3:$D$669,2,0) -> miếng dán silicon điện thoại | D40: =VLOOKUP(B40,'Danh mục hàng hóa'!$C$3:$M$656,6,0) -> #N/A | E40: 1 | F40: =D40*E40 -> #N/A
...

Sheet Doanh thu
A1: Doanh Thu
A2: Mã hàng | B2: Tên quy cách | C2: ĐVT | D2: Đơn giá bán | E2: Số lượng xuất | F2: Xuất | G2: Note | H2: Doanh thu | I2: =SUM(H3:H5481) -> 275743411
A3: MKD01 | B3: =VLOOKUP(A3,'Danh mục hàng hóa'!$C$3:$D$643,2,0) -> Móc khóa đôi heo | C3: =VLOOKUP(A3,'Danh mục hàng hóa'!$C$3:$E$656,3,0) -> cái | D3: =VLOOKUP(A3,'Danh mục hàng hóa'!$C$3:$M$656,6,0) -> 56580 | E3: 1 | F3: =D3*E3 -> 56580 | H3: 44051
A4: CT04 | B4: =VLOOKUP(A4,'Danh mục hàng hóa'!$C$3:$D$643,2,0) -> Cài tóc kem | C4: =VLOOKUP(A4,'Danh mục hàng hóa'!$C$3:$E$656,3,0) -> cái | D4: =VLOOKUP(A4,'Danh mục hàng hóa'!$C$3:$M$656,6,0) -> 21000 | E4: 1 | F4: =D4*E4 -> 21000 | H4: 47664
A5: TC004 | B5: =VLOOKUP(A5,'Danh mục hàng hóa'!$C$3:$D$643,2,0) -> Trâm cài 04 | C5: =VLOOKUP(A5,'Danh mục hàng hóa'!$C$3:$E$656,3,0) -> cây | D5: =VLOOKUP(A5,'Danh mục hàng hóa'!$C$3:$M$656,6,0) -> 11040 | E5: 1 | F5: =D5*E5 -> 11040
A6: TC009 | B6: =VLOOKUP(A6,'Danh mục hàng hóa'!$C$3:$D$643,2,0) -> Trâm cài 09 | C6: =VLOOKUP(A6,'Danh mục hàng hóa'!$C$3:$E$656,3,0) -> cây | D6: =VLOOKUP(A6,'Danh mục hàng hóa'!$C$3:$M$656,6,0) -> 28520 | E6: 1 | F6: =D6*E6 -> 28520
A7: MCC | B7: =VLOOKUP(A7,'Danh mục hàng hóa'!$C$3:$D$643,2,0) -> Mèo chong chóng | C7: =VLOOKUP(A7,'Danh mục hàng hóa'!$C$3:$E$656,3,0) -> cái | D7: =VLOOKUP(A7,'Danh mục hàng hóa'!$C$3:$M$656,6,0) -> 54740 | E7: 1 | F7: =D7*E7 -> 54740 | H7: 49114
A8: TCB17 | B8: =VLOOKUP(A8,'Danh mục hàng hóa'!$C$3:$D$643,2,0) -> Túi chườm bụng vịt vàng 500ml | C8: =VLOOKUP(A8,'Danh mục hàng hóa'!$C$3:$E$656,3,0) -> túi | D8: =VLOOKUP(A8,'Danh mục hàng hóa'!$C$3:$M$656,6,0) -> 72250 | E8: 1 | F8: =D8*E8 -> 72250 | H8: 56502
A9: KTB03 | B9: =VLOOKUP(A9,'Danh mục hàng hóa'!$C$3:$D$643,2,0) -> Kẹp tóc bướm xanh ngọc | C9: =VLOOKUP(A9,'Danh mục hàng hóa'!$C$3:$E$656,3,0) -> cái | D9: =VLOOKUP(A9,'Danh mục hàng hóa'!$C$3:$M$656,6,0) -> 38000 | E9: 1 | F9: =D9*E9 -> 38000 | H9: 77472
A10: KTB04 | B10: =VLOOKUP(A10,'Danh mục hàng hóa'!$C$3:$D$643,2,0) -> Kẹp tóc bướm xanh tím | C10: =VLOOKUP(A10,'Danh mục hàng hóa'!$C$3:$E$656,3,0) -> cái | D10: =VLOOKUP(A10,'Danh mục hàng hóa'!$C$3:$M$656,6,0) -> 40000 | E10: 1 | F10: =D10*E10 -> 40000
A11: MKD01 | B11: =VLOOKUP(A11,'Danh mục hàng hóa'!$C$3:$D$643,2,0) -> Móc khóa đôi heo | C11: =VLOOKUP(A11,'Danh mục hàng hóa'!$C$3:$E$656,3,0) -> cái | D11: =VLOOKUP(A11,'Danh mục hàng hóa'!$C$3:$M$656,6,0) -> 56580 | E11: 1 | F11: =D11*E11 -> 56580 | H11: 44811
A12: KTB05 | B12: =VLOOKUP(A12,'Danh mục hàng hóa'!$C$3:$D$643,2,0) -> Kẹp tóc bướm tím | C12: =VLOOKUP(A12,'Danh mục hàng hóa'!$C$3:$E$656,3,0) -> cái | D12: =VLOOKUP(A12,'Danh mục hàng hóa'!$C$3:$M$656,6,0) -> 38000 | E12: 1 | F12: =D12*E12 -> 38000 | H12: 60132
A13: KTB02 | B13: =VLOOKUP(A13,'Danh mục hàng hóa'!$C$3:$D$643,2,0) -> Kẹp tóc bướm hồng | C13: =VLOOKUP(A13,'Danh mục hàng hóa'!$C$3:$E$656,3,0) -> cái | D13: =VLOOKUP(A13,'Danh mục hàng hóa'!$C$3:$M$656,6,0) -> 40000 | E13: 1 | F13: =D13*E13 -> 40000
A14: KTB05 | B14: =VLOOKUP(A14,'Danh mục hàng hóa'!$C$3:$D$643,2,0) -> Kẹp tóc bướm tím | C14: =VLOOKUP(A14,'Danh mục hàng hóa'!$C$3:$E$656,3,0) -> cái | D14: =VLOOKUP(A14,'Danh mục hàng hóa'!$C$3:$M$656,6,0) -> 38000 | E14: 1 | F14: =D14*E14 -> 38000 | H14: 33140
A15: KTB04 | B15: =VLOOKUP(A15,'Danh mục hàng hóa'!$C$3:$D$643,2,0) -> Kẹp tóc bướm xanh tím | C15: =VLOOKUP(A15,'Danh mục hàng hóa'!$C$3:$E$656,3,0) -> cái | D15: =VLOOKUP(A15,'Danh mục hàng hóa'!$C$3:$M$656,6,0) -> 40000 | E15: 1 | F15: =D15*E15 -> 40000 | H15: 33440
A16: KTB03 | B16: =VLOOKUP(A16,'Danh mục hàng hóa'!$C$3:$D$643,2,0) -> Kẹp tóc bướm xanh ngọc | C16: =VLOOKUP(A16,'Danh mục hàng hóa'!$C$3:$E$656,3,0) -> cái | D16: =VLOOKUP(A16,'Danh mục hàng hóa'!$C$3:$M$656,6,0) -> 38000 | E16: 1 | F16: =D16*E16 -> 38000 | H16: 33440
A17: KTB01 | B17: =VLOOKUP(A17,'Danh mục hàng hóa'!$C$3:$D$643,2,0) -> Kẹp tóc bướm hồng phấn | C17: =VLOOKUP(A17,'Danh mục hàng hóa'!$C$3:$E$656,3,0) -> cái | D17: =VLOOKUP(A17,'Danh mục hàng hóa'!$C$3:$M$656,6,0) -> 38000 | E17: 1 | F17: =D17*E17 -> 38000 | H17: 32340
A18: KTB03 | B18: =VLOOKUP(A18,'Danh mục hàng hóa'!$C$3:$D$643,2,0) -> Kẹp tóc bướm xanh ngọc | C18: =VLOOKUP(A18,'Danh mục hàng hóa'!$C$3:$E$656,3,0) -> cái | D18: =VLOOKUP(A18,'Danh mục hàng hóa'!$C$3:$M$656,6,0) -> 38000 | E18: 1 | F18: =D18*E18 -> 38000 | H18: 33380
A19: KTB04 | B19: =VLOOKUP(A19,'Danh mục hàng hóa'!$C$3:$D$643,2,0) -> Kẹp tóc bướm xanh tím | C19: =VLOOKUP(A19,'Danh mục hàng hóa'!$C$3:$E$656,3,0) -> cái | D19: =VLOOKUP(A19,'Danh mục hàng hóa'!$C$3:$M$656,6,0) -> 40000 | E19: 1 | F19: =D19*E19 -> 40000 | H19: 33380
A20: KTB03 | B20: =VLOOKUP(A20,'Danh mục hàng hóa'!$C$3:$D$643,2,0) -> Kẹp tóc bướm xanh ngọc | C20: =VLOOKUP(A20,'Danh mục hàng hóa'!$C$3:$E$656,3,0) -> cái | D20: =VLOOKUP(A20,'Danh mục hàng hóa'!$C$3:$M$656,6,0) -> 38000 | E20: 1 | F20: =D20*E20 -> 38000 | H20: 60132
A21: KTB02 | B21: =VLOOKUP(A21,'Danh mục hàng hóa'!$C$3:$D$643,2,0) -> Kẹp tóc bướm hồng | C21: =VLOOKUP(A21,'Danh mục hàng hóa'!$C$3:$E$656,3,0) -> cái | D21: =VLOOKUP(A21,'Danh mục hàng hóa'!$C$3:$M$656,6,0) -> 40000 | E21: 1 | F21: =D21*E21 -> 40000
A22: KTB01 | B22: =VLOOKUP(A22,'Danh mục hàng hóa'!$C$3:$D$643,2,0) -> Kẹp tóc bướm hồng phấn | C22: =VLOOKUP(A22,'Danh mục hàng hóa'!$C$3:$E$656,3,0) -> cái | D22: =VLOOKUP(A22,'Danh mục hàng hóa'!$C$3:$M$656,6,0) -> 38000 | E22: 1 | F22: =D22*E22 -> 38000 | H22: 271039
A23: KTHS01 | B23: =VLOOKUP(A23,'Danh mục hàng hóa'!$C$3:$D$643,2,0) -> Kẹp tóc hoa sứ tím | C23: =VLOOKUP(A23,'Danh mục hàng hóa'!$C$3:$E$656,3,0) -> cái | D23: =VLOOKUP(A23,'Danh mục hàng hóa'!$C$3:$M$656,6,0) -> 18500 | E23: 1 | F23: =D23*E23 -> 18500
A24: KTB07 | B24: =VLOOKUP(A24,'Danh mục hàng hóa'!$C$3:$D$643,2,0) -> Kẹp tóc bướm kem | C24: =VLOOKUP(A24,'Danh mục hàng hóa'!$C$3:$E$656,3,0) -> cái | D24: =VLOOKUP(A24,'Danh mục hàng hóa'!$C$3:$M$656,6,0) -> 38000 | E24: 1 | F24: =D24*E24 -> 38000
A25: KTHS03 | B25: =VLOOKUP(A25,'Danh mục hàng hóa'!$C$3:$D$643,2,0) -> Kẹp tóc hoa sứ vàng | C25: =VLOOKUP(A25,'Danh mục hàng hóa'!$C$3:$E$656,3,0) -> cái | D25: =VLOOKUP(A25,'Danh mục hàng hóa'!$C$3:$M$656,6,0) -> 18500 | E25: 1 | F25: =D25*E25 -> 18500
A26: KTB03 | B26: =VLOOKUP(A26,'Danh mục hàng hóa'!$C$3:$D$643,2,0) -> Kẹp tóc bướm xanh ngọc | C26: =VLOOKUP(A26,'Danh mục hàng hóa'!$C$3:$E$656,3,0) -> cái | D26: =VLOOKUP(A26,'Danh mục hàng hóa'!$C$3:$M$656,6,0) -> 38000 | E26: 1 | F26: =D26*E26 -> 38000
A27: KTHS06 | B27: =VLOOKUP(A27,'Danh mục hàng hóa'!$C$3:$D$643,2,0) -> Kẹp tóc hoa sứ xanh | C27: =VLOOKUP(A27,'Danh mục hàng hóa'!$C$3:$E$656,3,0) -> cái | D27: =VLOOKUP(A27,'Danh mục hàng hóa'!$C$3:$M$656,6,0) -> 18500 | E27: 1 | F27: =D27*E27 -> 18500
A28: KTB04 | B28: =VLOOKUP(A28,'Danh mục hàng hóa'!$C$3:$D$643,2,0) -> Kẹp tóc bướm xanh tím | C28: =VLOOKUP(A28,'Danh mục hàng hóa'!$C$3:$E$656,3,0) -> cái | D28: =VLOOKUP(A28,'Danh mục hàng hóa'!$C$3:$M$656,6,0) -> 40000 | E28: 1 | F28: =D28*E28 -> 40000
A29: KTHS02 | B29: =VLOOKUP(A29,'Danh mục hàng hóa'!$C$3:$D$643,2,0) -> Kẹp tóc hoa sứ hồng | C29: =VLOOKUP(A29,'Danh mục hàng hóa'!$C$3:$E$656,3,0) -> cái | D29: =VLOOKUP(A29,'Danh mục hàng hóa'!$C$3:$M$656,6,0) -> 18500 | E29: 1 | F29: =D29*E29 -> 18500
A30: KTB05 | B30: =VLOOKUP(A30,'Danh mục hàng hóa'!$C$3:$D$643,2,0) -> Kẹp tóc bướm tím | C30: =VLOOKUP(A30,'Danh mục hàng hóa'!$C$3:$E$656,3,0) -> cái | D30: =VLOOKUP(A30,'Danh mục hàng hóa'!$C$3:$M$656,6,0) -> 38000 | E30: 1 | F30: =D30*E30 -> 38000
A31: KTHS05 | B31: =VLOOKUP(A31,'Danh mục hàng hóa'!$C$3:$D$643,2,0) -> Kẹp tóc hoa sứ đỏ | C31: =VLOOKUP(A31,'Danh mục hàng hóa'!$C$3:$E$656,3,0) -> cái | D31: =VLOOKUP(A31,'Danh mục hàng hóa'!$C$3:$M$656,6,0) -> 18500 | E31: 1 | F31: =D31*E31 -> 18500
A32: KTB02 | B32: =VLOOKUP(A32,'Danh mục hàng hóa'!$C$3:$D$643,2,0) -> Kẹp tóc bướm hồng | C32: =VLOOKUP(A32,'Danh mục hàng hóa'!$C$3:$E$656,3,0) -> cái | D32: =VLOOKUP(A32,'Danh mục hàng hóa'!$C$3:$M$656,6,0) -> 40000 | E32: 1 | F32: =D32*E32 -> 40000
A33: KTHS04 | B33: =VLOOKUP(A33,'Danh mục hàng hóa'!$C$3:$D$643,2,0) -> Kẹp tóc hoa sứ cam | C33: =VLOOKUP(A33,'Danh mục hàng hóa'!$C$3:$E$656,3,0) -> cái | D33: =VLOOKUP(A33,'Danh mục hàng hóa'!$C$3:$M$656,6,0) -> 18500 | E33: 1 | F33: =D33*E33 -> 18500
A34: KTB01 | B34: =VLOOKUP(A34,'Danh mục hàng hóa'!$C$3:$D$643,2,0) -> Kẹp tóc bướm hồng phấn | C34: =VLOOKUP(A34,'Danh mục hàng hóa'!$C$3:$E$656,3,0) -> cái | D34: =VLOOKUP(A34,'Danh mục hàng hóa'!$C$3:$M$656,6,0) -> 38000 | E34: 1 | F34: =D34*E34 -> 38000 | H34: 90288
A35: KTB04 | B35: =VLOOKUP(A35,'Danh mục hàng hóa'!$C$3:$D$643,2,0) -> Kẹp tóc bướm xanh tím | C35: =VLOOKUP(A35,'Danh mục hàng hóa'!$C$3:$E$656,3,0) -> cái | D35: =VLOOKUP(A35,'Danh mục hàng hóa'!$C$3:$M$656,6,0) -> 40000 | E35: 1 | F35: =D35*E35 -> 40000
A36: KTB05 | B36: =VLOOKUP(A36,'Danh mục hàng hóa'!$C$3:$D$643,2,0) -> Kẹp tóc bướm tím | C36: =VLOOKUP(A36,'Danh mục hàng hóa'!$C$3:$E$656,3,0) -> cái | D36: =VLOOKUP(A36,'Danh mục hàng hóa'!$C$3:$M$656,6,0) -> 38000 | E36: 1 | F36: =D36*E36 -> 38000
A37: MKD03 | B37: =VLOOKUP(A37,'Danh mục hàng hóa'!$C$3:$D$643,2,0) -> Móc khóa đôi corgy | C37: =VLOOKUP(A37,'Danh mục hàng hóa'!$C$3:$E$656,3,0) -> cái | D37: =VLOOKUP(A37,'Danh mục hàng hóa'!$C$3:$M$656,6,0) -> 56580 | E37: 1 | F37: =D37*E37 -> 56580 | H37: 44751
